Workbook

Sheet Dimensionador
A1: DIMENSIONADOR DE BESS | SECRETARIA DE INFRA ESTRUTURA | LOAD SHIFTING
A2: Preencha as células em AZUL. A planilha calcula o número sugerido e todos os indicadores.
A4: ① ENTRADA: CONSUMO E DIMENSIONAMENTO
B5: Consumo médio de ponta desejado | C5: 2350 | D5: kWh/mês | E5: Média mensal de energia a deslocar do HP para HFP
B6: ⟹ Nº sugerido de BESS (calculado) | C6: =CEILING(C5/(Premissas!$C$12),1) -> 1 | D6: unidades | E6: Arredondamento para cima (energia útil 1 BESS = C12 da aba Premissas)
B7: ✏️ Nº de BESS adotado (você define) | C7: 1 | D7: unidades | E7: ⬅ EDITE AQUI: confirme ou altere o número sugerido acima
B8: CAPEX total negociado (todos os BESS) | C8: 520000 | D8: R$ | E8: Valor total com instalação, frete e comissionamento
A10: ② PARÂMETROS DO EQUIPAMENTO (vinculados à aba Premissas)
B11: Potência nominal | C11: =Premissas!C5 -> 241 | D11: kW
B12: DoD | C12: =Premissas!C6 -> 1 | D12: p.u.
B13: η BESS round-trip | C13: =Premissas!C7 -> 0.9556 | D13: p.u.
B14: η Elétrica | C14: =Premissas!C8 -> 0.98 | D14: p.u.
B15: η Operacional | C15: =Premissas!C9 -> 0.99 | D15: p.u.
B16: Dias úteis/mês | C16: =Premissas!C10 -> 21 | D16: dias
B17: Energia útil/ciclo | C17: =Premissas!C11 -> 223.43667 | D17: kWh/ciclo
B18: Energia útil/mês 1 BESS | C18: =Premissas!C12 -> 4692.1701 | D18: kWh/mês
B19: Energia carga/mês 1 BESS | C19: =Premissas!C13 -> 5458.8219 | D19: kWh/mês
A21: ③ ENERGIA CALCULADA COM O Nº DE BESS ADOTADO
B22: Energia útil/mês (N BESS) | C22: =$C$7*Premissas!$C$12 -> 4692.1701 | E22: N BESS × energia útil 1 BESS
B23: Energia carga/mês (N BESS) | C23: =$C$7*Premissas!$C$13 -> 5458.8219 | E23: N BESS × energia de carga 1 BESS
B24: Cobertura do consumo desejado | C24: =C22/C5 -> 1.9966681 | E24: Energia disponível ÷ consumo de ponta médio
B25: Receita HP ano 1 (base) | C25: =C22*Premissas!$C$21*12 -> 165154.91 | E25: Energia útil × tarifa HP × 12 meses
B26: Custo HFP ano 1 (base) | C26: =C23*Premissas!$C$20*12 -> 8020.0747 | E26: Energia de carga × tarifa HFP × 12 meses
B27: Economia bruta ano 1 (base) | C27: =C25-C26 -> 157134.83 | E27: Receita HP − Custo HFP (sem degradação)
B28: O&M ano 1 (N BESS) | C28: =Premissas!$C$25 -> 7800 | E28: N BESS × O&M unitário
B29: Economia líquida ano 1 (base) | C29: =C27-C28 -> 149334.83 | E29: Após O&M, sem degradação ainda
A31: ④ TARIFAS (vinculadas à aba Premissas)
B32: Tarifa HFP total | C32: =Premissas!$C$20 -> 0.12243293
B33: Tarifa HP total | C33: =Premissas!$C$21 -> 2.933165
B34: Delta HP − HFP | C34: =Premissas!$C$22 -> 2.810732
B35: Reajuste tarifário anual | C35: =Premissas!$C$26 -> 0.08
A37: ⑤ INDICADORES FINANCEIROS — RESULTADO FINAL
B38: VPL (TMA Premissas) | C38: ='Fluxo 20 Anos'!C249 -> 1088598.1
B39: TIR (a.a.) | C39: ='Fluxo 20 Anos'!C250 -> 0.33737693
B40: Payback (anos) | C40: ='Fluxo 20 Anos'!C252 -> 3.3098908
B41: Payback (meses) | C41: ='Fluxo 20 Anos'!C251 -> 39.71869
B42: Acumulado Ano 20 | C42: ='Fluxo 20 Anos'!C253 -> 4765590.3
B43: Economia Total 20 anos (líq.) | C43: ='Fluxo 20 Anos'!C254 -> 5285590.3
B45: TMA utilizada no VPL: ver Premissas (célula C31) | Reajuste O&M: C30 | Horizonte: 20 anos

Sheet Fluxo 20 Anos
A1: FLUXO DE CAIXA — MÊS A MÊS — 20 ANOS | N BESS DINÂMICO
A2: SOH interpolado mensalmente | Reajuste tarifário anual | Degradação contínua ao longo dos 240 meses
A4: Ano | B4: Mês | C4: SOH Mês | D4: Reajuste Tarifário | E4: Receita HP (R$) | F4: Custo HFP (R$) | G4: O&M (R$/mês) | H4: Eco. Bruta (R$/mês) | I4: Eco. Líq. (R$/mês) | J4: Acumulado (R$) | K4: Eco. Acum. (sem CAPEX) | L4: Ref. Ponto Equilíbrio
A5: 0 | B5: Invest. | I5: =-Dimensionador!$C$8 -> -520000 | J5: =-Dimensionador!$C$8 -> -520000 | K5: =0 -> 0 | M5: =-Dimensionador!$C$8 -> -520000 | N5: =-Dimensionador!$C$8 -> -520000
A6: 1 | B6: Jan | C6: =Premissas!$C$31+0*(Premissas!$C$32-Premissas!$C$31) -> 1 | D6: =(1+Premissas!$C$26)^(0) -> 1 | E6: =Dimensionador!$C$22*(Premissas!$C$31+0*(Premissas!$C$32-Premissas!$C$31))*Premissas!$C$21*(1+Premissas!$C$26)^(0) -> 13762.909 | F6: =Dimensionador!$C$23*(Premissas!$C$31+0*(Premissas!$C$32-Premissas!$C$31))*Premissas!$C$20*(1+Premissas!$C$26)^(0) -> 668.33956 | G6: =Premissas!$C$25*(1+Premissas!$C$27)^(0)/12 -> 650 | H6: =E6-F6 -> 13094.569 | I6: =H6-G6 -> 12444.569 | J6: =J5+I6 -> -507555.43 | K6: =I6 -> 12444.569 | L6: "" | M6: =I6 -> 12444.569 | N6: =SUM(I6:I17) -> 147246.25
A7: 1 | B7: Fev | C7: =Premissas!$C$31+0.0833333333*(Premissas!$C$32-Premissas!$C$31) -> 0.99758333 | D7: =(1+Premissas!$C$26)^(0) -> 1 | E7: =Dimensionador!$C$22*(Premissas!$C$31+0.0833333333*(Premissas!$C$32-Premissas!$C$31))*Premissas!$C$21*(1+Premissas!$C$26)^(0) -> 13729.649 | F7: =Dimensionador!$C$23*(Premissas!$C$31+0.0833333333*(Premissas!$C$32-Premissas!$C$31))*Premissas!$C$20*(1+Premissas!$C$26)^(0) -> 666.72441 | G7: =Premissas!$C$25*(1+Premissas!$C$27)^(0)/12 -> 650 | H7: =E7-F7 -> 13062.924 | I7: =H7-G7 -> 12412.924 | J7: =J6+I7 -> -495142.51 | K7: =K6+I7 -> 24857.494 | L7: =IF(AND(J7>=0,J6<0),"✅ PAYBACK","") | M7: =I7 -> 12412.924 | N7: =SUM(I18:I29) -> 154961.18
A8: 1 | B8: Mar | C8: =Premissas!$C$31+0.1666666667*(Premissas!$C$32-Premissas!$C$31) -> 0.99516667 | D8: =(1+Premissas!$C$26)^(0) -> 1 | E8: =Dimensionador!$C$22*(Premissas!$C$31+0.1666666667*(Premissas!$C$32-Premissas!$C$31))*Premissas!$C$21*(1+Premissas!$C$26)^(0) -> 13696.388 | F8: =Dimensionador!$C$23*(Premissas!$C$31+0.1666666667*(Premissas!$C$32-Premissas!$C$31))*Premissas!$C$20*(1+Premissas!$C$26)^(0) -> 665.10925 | G8: =Premissas!$C$25*(1+Premissas!$C$27)^(0)/12 -> 650 | H8: =E8-F8 -> 13031.279 | I8: =H8-G8 -> 12381.279 | J8: =J7+I8 -> -482761.23 | K8: =K7+I8 -> 37238.773 | L8: =IF(AND(J8>=0,J7<0),"✅ PAYBACK","") | M8: =I8 -> 12381.279 | N8: =SUM(I30:I41) -> 163712.29
A9: 1 | B9: Abr | C9: =Premissas!$C$31+0.25*(Premissas!$C$32-Premissas!$C$31) -> 0.99275 | D9: =(1+Premissas!$C$26)^(0) -> 1 | E9: =Dimensionador!$C$22*(Premissas!$C$31+0.25*(Premissas!$C$32-Premissas!$C$31))*Premissas!$C$21*(1+Premissas!$C$26)^(0) -> 13663.128 | F9: =Dimensionador!$C$23*(Premissas!$C$31+0.25*(Premissas!$C$32-Premissas!$C$31))*Premissas!$C$20*(1+Premissas!$C$26)^(0) -> 663.4941 | G9: =Premissas!$C$25*(1+Premissas!$C$27)^(0)/12 -> 650 | H9: =E9-F9 -> 12999.634 | I9: =H9-G9 -> 12349.634 | J9: =J8+I9 -> -470411.59 | K9: =K8+I9 -> 49588.407 | L9: =IF(AND(J9>=0,J8<0),"✅ PAYBACK","") | M9: =I9 -> 12349.634 | N9: =SUM(I42:I53) -> 173156.91
A10: 1 | B10: Mai | C10: =Premissas!$C$31+0.3333333333*(Premissas!$C$32-Premissas!$C$31) -> 0.99033333 | D10: =(1+Premissas!$C$26)^(0) -> 1 | E10: =Dimensionador!$C$22*(Premissas!$C$31+0.3333333333*(Premissas!$C$32-Premissas!$C$31))*Premissas!$C$21*(1+Premissas!$C$26)^(0) -> 13629.868 | F10: =Dimensionador!$C$23*(Premissas!$C$31+0.3333333333*(Premissas!$C$32-Premissas!$C$31))*Premissas!$C$20*(1+Premissas!$C$26)^(0) -> 661.87894 | G10: =Premissas!$C$25*(1+Premissas!$C$27)^(0)/12 -> 650 | H10: =E10-F10 -> 12967.989 | I10: =H10-G10 -> 12317.989 | J10: =J9+I10 -> -458093.6 | K10: =K9+I10 -> 61906.395 | L10: =IF(AND(J10>=0,J9<0),"✅ PAYBACK","") | M10: =I10 -> 12317.989 | N10: =SUM(I54:I65) -> 183258.01
A11: 1 | B11: Jun | C11: =Premissas!$C$31+0.4166666667*(Premissas!$C$32-Premissas!$C$31) -> 0.98791667 | D11: =(1+Premissas!$C$26)^(0) -> 1 | E11: =Dimensionador!$C$22*(Premissas!$C$31+0.4166666667*(Premissas!$C$32-Premissas!$C$31))*Premissas!$C$21*(1+Premissas!$C$26)^(0) -> 13596.607 | F11: =Dimensionador!$C$23*(Premissas!$C$31+0.4166666667*(Premissas!$C$32-Premissas!$C$31))*Premissas!$C$20*(1+Premissas!$C$26)^(0) -> 660.26379 | G11: =Premissas!$C$25*(1+Premissas!$C$27)^(0)/12 -> 650 | H11: =E11-F11 -> 12936.343 | I11: =H11-G11 -> 12286.343 | J11: =J10+I11 -> -445807.26 | K11: =K10+I11 -> 74192.739 | L11: =IF(AND(J11>=0,J10<0),"✅ PAYBACK","") | M11: =I11 -> 12286.343 | N11: =SUM(I66:I77) -> 194076.65
A12: 1 | B12: Jul | C12: =Premissas!$C$31+0.5*(Premissas!$C$32-Premissas!$C$31) -> 0.9855 | D12: =(1+Premissas!$C$26)^(0) -> 1 | E12: =Dimensionador!$C$22*(Premissas!$C$31+0.5*(Premissas!$C$32-Premissas!$C$31))*Premissas!$C$21*(1+Premissas!$C$26)^(0) -> 13563.347 | F12: =Dimensionador!$C$23*(Premissas!$C$31+0.5*(Premissas!$C$32-Premissas!$C$31))*Premissas!$C$20*(1+Premissas!$C$26)^(0) -> 658.64864 | G12: =Premissas!$C$25*(1+Premissas!$C$27)^(0)/12 -> 650 | H12: =E12-F12 -> 12904.698 | I12: =H12-G12 -> 12254.698 | J12: =J11+I12 -> -433552.56 | K12: =K11+I12 -> 86447.437 | L12: =IF(AND(J12>=0,J11<0),"✅ PAYBACK","") | M12: =I12 -> 12254.698 | N12: =SUM(I78:I89) -> 205566.54
A13: 1 | B13: Ago | C13: =Premissas!$C$31+0.5833333333*(Premissas!$C$32-Premissas!$C$31) -> 0.98308333 | D13: =(1+Premissas!$C$26)^(0) -> 1 | E13: =Dimensionador!$C$22*(Premissas!$C$31+0.5833333333*(Premissas!$C$32-Premissas!$C$31))*Premissas!$C$21*(1+Premissas!$C$26)^(0) -> 13530.087 | F13: =Dimensionador!$C$23*(Premissas!$C$31+0.5833333333*(Premissas!$C$32-Premissas!$C$31))*Premissas!$C$20*(1+Premissas!$C$26)^(0) -> 657.03348 | G13: =Premissas!$C$25*(1+Premissas!$C$27)^(0)/12 -> 650 | H13: =E13-F13 -> 12873.053 | I13: =H13-G13 -> 12223.053 | J13: =J12+I13 -> -421329.51 | K13: =K12+I13 -> 98670.49 | L13: =IF(AND(J13>=0,J12<0),"✅ PAYBACK","") | M13: =I13 -> 12223.053 | N13: =SUM(I90:I101) -> 217630.12
A14: 1 | B14: Set | C14: =Premissas!$C$31+0.6666666667*(Premissas!$C$32-Premissas!$C$31) -> 0.98066667 | D14: =(1+Premissas!$C$26)^(0) -> 1 | E14: =Dimensionador!$C$22*(Premissas!$C$31+0.6666666667*(Premissas!$C$32-Premissas!$C$31))*Premissas!$C$21*(1+Premissas!$C$26)^(0) -> 13496.826 | F14: =Dimensionador!$C$23*(Premissas!$C$31+0.6666666667*(Premissas!$C$32-Premissas!$C$31))*Premissas!$C$20*(1+Premissas!$C$26)^(0) -> 655.41833 | G14: =Premissas!$C$25*(1+Premissas!$C$27)^(0)/12 -> 650 | H14: =E14-F14 -> 12841.408 | I14: =H14-G14 -> 12191.408 | J14: =J13+I14 -> -409138.1 | K14: =K13+I14 -> 110861.9 | L14: =IF(AND(J14>=0,J13<0),"✅ PAYBACK","") | M14: =I14 -> 12191.408 | N14: =SUM(I102:I113) -> 230418.26
A15: 1 | B15: Out | C15: =Premissas!$C$31+0.75*(Premissas!$C$32-Premissas!$C$31) -> 0.97825 | D15: =(1+Premissas!$C$26)^(0) -> 1 | E15: =Dimensionador!$C$22*(Premissas!$C$31+0.75*(Premissas!$C$32-Premissas!$C$31))*Premissas!$C$21*(1+Premissas!$C$26)^(0) -> 13463.566 | F15: =Dimensionador!$C$23*(Premissas!$C$31+0.75*(Premissas!$C$32-Premissas!$C$31))*Premissas!$C$20*(1+Premissas!$C$26)^(0) -> 653.80318 | G15: =Premissas!$C$25*(1+Premissas!$C$27)^(0)/12 -> 650 | H15: =E15-F15 -> 12809.763 | I15: =H15-G15 -> 12159.763 | J15: =J14+I15 -> -396978.34 | K15: =K14+I15 -> 123021.66 | L15: =IF(AND(J15>=0,J14<0),"✅ PAYBACK","") | M15: =I15 -> 12159.763 | N15: =SUM(I114:I125) -> 243861.87
A16: 1 | B16: Nov | C16: =Premissas!$C$31+0.8333333333*(Premissas!$C$32-Premissas!$C$31) -> 0.97583333 | D16: =(1+Premissas!$C$26)^(0) -> 1 | E16: =Dimensionador!$C$22*(Premissas!$C$31+0.8333333333*(Premissas!$C$32-Premissas!$C$31))*Premissas!$C$21*(1+Premissas!$C$26)^(0) -> 13430.305 | F16: =Dimensionador!$C$23*(Premissas!$C$31+0.8333333333*(Premissas!$C$32-Premissas!$C$31))*Premissas!$C$20*(1+Premissas!$C$26)^(0) -> 652.18802 | G16: =Premissas!$C$25*(1+Premissas!$C$27)^(0)/12 -> 650 | H16: =E16-F16 -> 12778.117 | I16: =H16-G16 -> 12128.117 | J16: =J15+I16 -> -384850.22 | K16: =K15+I16 -> 135149.78 | L16: =IF(AND(J16>=0,J15<0),"✅ PAYBACK","") | M16: =I16 -> 12128.117 | N16: =SUM(I126:I137) -> 258084.29
A17: 1 | B17: Dez | C17: =Premissas!$C$31+0.9166666667*(Premissas!$C$32-Premissas!$C$31) -> 0.97341667 | D17: =(1+Premissas!$C$26)^(0) -> 1 | E17: =Dimensionador!$C$22*(Premissas!$C$31+0.9166666667*(Premissas!$C$32-Premissas!$C$31))*Premissas!$C$21*(1+Premissas!$C$26)^(0) -> 13397.045 | F17: =Dimensionador!$C$23*(Premissas!$C$31+0.9166666667*(Premissas!$C$32-Premissas!$C$31))*Premissas!$C$20*(1+Premissas!$C$26)^(0) -> 650.57287 | G17: =Premissas!$C$25*(1+Premissas!$C$27)^(0)/12 -> 650 | H17: =E17-F17 -> 12746.472 | I17: =H17-G17 -> 12096.472 | J17: =J16+I17 -> -372753.75 | K17: =K16+I17 -> 147246.25 | L17: =IF(AND(J17>=0,J16<0),"✅ PAYBACK","") | M17: =I17 -> 12096.472 | N17: =SUM(I138:I149) -> 273225.13
A18: 2 | B18: Jan | C18: =Premissas!$C$32+0*(Premissas!$C$33-Premissas!$C$32) -> 0.971 | D18: =(1+Premissas!$C$26)^(1) -> 1.08 | E18: =Dimensionador!$C$22*(Premissas!$C$32+0*(Premissas!$C$33-Premissas!$C$32))*Premissas!$C$21*(1+Premissas!$C$26)^(1) -> 14432.887 | F18: =Dimensionador!$C$23*(Premissas!$C$32+0*(Premissas!$C$33-Premissas!$C$32))*Premissas!$C$20*(1+Premissas!$C$26)^(1) -> 700.87433 | G18: =Premissas!$C$25*(1+Premissas!$C$27)^(1)/12 -> 669.5 | H18: =E18-F18 -> 13732.013 | I18: =H18-G18 -> 13062.513 | J18: =J17+I18 -> -359691.24 | K18: =K17+I18 -> 160308.76 | L18: =IF(AND(J18>=0,J17<0),"✅ PAYBACK","") | M18: =I18 -> 13062.513 | N18: =SUM(I150:I161) -> 289077.58
A19: 2 | B19: Fev | C19: =Premissas!$C$32+0.0833333333*(Premissas!$C$33-Premissas!$C$32) -> 0.96908333 | D19: =(1+Premissas!$C$26)^(1) -> 1.08 | E19: =Dimensionador!$C$22*(Premissas!$C$32+0.0833333333*(Premissas!$C$33-Premissas!$C$32))*Premissas!$C$21*(1+Premissas!$C$26)^(1) -> 14404.398 | F19: =Dimensionador!$C$23*(Premissas!$C$32+0.0833333333*(Premissas!$C$33-Premissas!$C$32))*Premissas!$C$20*(1+Premissas!$C$26)^(1) -> 699.49087 | G19: =Premissas!$C$25*(1+Premissas!$C$27)^(1)/12 -> 669.5 | H19: =E19-F19 -> 13704.907 | I19: =H19-G19 -> 13035.407 | J19: =J18+I19 -> -346655.83 | K19: =K18+I19 -> 173344.17 | L19: =IF(AND(J19>=0,J18<0),"✅ PAYBACK","") | M19: =I19 -> 13035.407 | N19: =SUM(I162:I173) -> 305922.27
A20: 2 | B20: Mar | C20: =Premissas!$C$32+0.1666666667*(Premissas!$C$33-Premissas!$C$32) -> 0.96716667 | D20: =(1+Premissas!$C$26)^(1) -> 1.08 | E20: =Dimensionador!$C$22*(Premissas!$C$32+0.1666666667*(Premissas!$C$33-Premissas!$C$32))*Premissas!$C$21*(1+Premissas!$C$26)^(1) -> 14375.909 | F20: =Dimensionador!$C$23*(Premissas!$C$32+0.1666666667*(Premissas!$C$33-Premissas!$C$32))*Premissas!$C$20*(1+Premissas!$C$26)^(1) -> 698.1074 | G20: =Premissas!$C$25*(1+Premissas!$C$27)^(1)/12 -> 669.5 | H20: =E20-F20 -> 13677.802 | I20: =H20-G20 -> 13008.302 | J20: =J19+I20 -> -333647.53 | K20: =K19+I20 -> 186352.47 | L20: =IF(AND(J20>=0,J19<0),"✅ PAYBACK","") | M20: =I20 -> 13008.302 | N20: =SUM(I174:I185) -> 323584.21
A21: 2 | B21: Abr | C21: =Premissas!$C$32+0.25*(Premissas!$C$33-Premissas!$C$32) -> 0.96525 | D21: =(1+Premissas!$C$26)^(1) -> 1.08 | E21: =Dimensionador!$C$22*(Premissas!$C$32+0.25*(Premissas!$C$33-Premissas!$C$32))*Premissas!$C$21*(1+Premissas!$C$26)^(1) -> 14347.42 | F21: =Dimensionador!$C$23*(Premissas!$C$32+0.25*(Premissas!$C$33-Premissas!$C$32))*Premissas!$C$20*(1+Premissas!$C$26)^(1) -> 696.72394 | G21: =Premissas!$C$25*(1+Premissas!$C$27)^(1)/12 -> 669.5 | H21: =E21-F21 -> 13650.696 | I21: =H21-G21 -> 12981.196 | J21: =J20+I21 -> -320666.33 | K21: =K20+I21 -> 199333.67 | L21: =IF(AND(J21>=0,J20<0),"✅ PAYBACK","") | M21: =I21 -> 12981.196 | N21: =SUM(I186:I197) -> 342313.99
A22: 2 | B22: Mai | C22: =Premissas!$C$32+0.3333333333*(Premissas!$C$33-Premissas!$C$32) -> 0.96333333 | D22: =(1+Premissas!$C$26)^(1) -> 1.08 | E22: =Dimensionador!$C$22*(Premissas!$C$32+0.3333333333*(Premissas!$C$33-Premissas!$C$32))*Premissas!$C$21*(1+Premissas!$C$26)^(1) -> 14318.931 | F22: =Dimensionador!$C$23*(Premissas!$C$32+0.3333333333*(Premissas!$C$33-Premissas!$C$32))*Premissas!$C$20*(1+Premissas!$C$26)^(1) -> 695.34048 | G22: =Premissas!$C$25*(1+Premissas!$C$27)^(1)/12 -> 669.5 | H22: =E22-F22 -> 13623.59 | I22: =H22-G22 -> 12954.09 | J22: =J21+I22 -> -307712.24 | K22: =K21+I22 -> 212287.76 | L22: =IF(AND(J22>=0,J21<0),"✅ PAYBACK","") | M22: =I22 -> 12954.09 | N22: =SUM(I198:I209) -> 362231.69
A23: 2 | B23: Jun | C23: =Premissas!$C$32+0.4166666667*(Premissas!$C$33-Premissas!$C$32) -> 0.96141667 | D23: =(1+Premissas!$C$26)^(1) -> 1.08 | E23: =Dimensionador!$C$22*(Premissas!$C$32+0.4166666667*(Premissas!$C$33-Premissas!$C$32))*Premissas!$C$21*(1+Premissas!$C$26)^(1) -> 14290.441 | F23: =Dimensionador!$C$23*(Premissas!$C$32+0.4166666667*(Premissas!$C$33-Premissas!$C$32))*Premissas!$C$20*(1+Premissas!$C$26)^(1) -> 693.95702 | G23: =Premissas!$C$25*(1+Premissas!$C$27)^(1)/12 -> 669.5 | H23: =E23-F23 -> 13596.484 | I23: =H23-G23 -> 12926.984 | J23: =J22+I23 -> -294785.26 | K23: =K22+I23 -> 225214.74 | L23: =IF(AND(J23>=0,J22<0),"✅ PAYBACK","") | M23: =I23 -> 12926.984 | N23: =SUM(I210:I221) -> 383115.04
A24: 2 | B24: Jul | C24: =Premissas!$C$32+0.5*(Premissas!$C$33-Premissas!$C$32) -> 0.9595 | D24: =(1+Premissas!$C$26)^(1) -> 1.08 | E24: =Dimensionador!$C$22*(Premissas!$C$32+0.5*(Premissas!$C$33-Premissas!$C$32))*Premissas!$C$21*(1+Premissas!$C$26)^(1) -> 14261.952 | F24: =Dimensionador!$C$23*(Premissas!$C$32+0.5*(Premissas!$C$33-Premissas!$C$32))*Premissas!$C$20*(1+Premissas!$C$26)^(1) -> 692.57355 | G24: =Premissas!$C$25*(1+Premissas!$C$27)^(1)/12 -> 669.5 | H24: =E24-F24 -> 13569.379 | I24: =H24-G24 -> 12899.879 | J24: =J23+I24 -> -281885.38 | K24: =K23+I24 -> 238114.62 | L24: =IF(AND(J24>=0,J23<0),"✅ PAYBACK","") | M24: =I24 -> 12899.879 | N24: =SUM(I222:I233) -> 405277.94
A25: 2 | B25: Ago | C25: =Premissas!$C$32+0.5833333333*(Premissas!$C$33-Premissas!$C$32) -> 0.95758333 | D25: =(1+Premissas!$C$26)^(1) -> 1.08 | E25: =Dimensionador!$C$22*(Premissas!$C$32+0.5833333333*(Premissas!$C$33-Premissas!$C$32))*Premissas!$C$21*(1+Premissas!$C$26)^(1) -> 14233.463 | F25: =Dimensionador!$C$23*(Premissas!$C$32+0.5833333333*(Premissas!$C$33-Premissas!$C$32))*Premissas!$C$20*(1+Premissas!$C$26)^(1) -> 691.19009 | G25: =Premissas!$C$25*(1+Premissas!$C$27)^(1)/12 -> 669.5 | H25: =E25-F25 -> 13542.273 | I25: =H25-G25 -> 12872.773 | J25: =J24+I25 -> -269012.61 | K25: =K24+I25 -> 250987.39 | L25: =IF(AND(J25>=0,J24<0),"✅ PAYBACK","") | M25: =I25 -> 12872.773 | N25: =SUM(I234:I245) -> 428870.06
A26: 2 | B26: Set | C26: =Premissas!$C$32+0.6666666667*(Premissas!$C$33-Premissas!$C$32) -> 0.95566667 | D26: =(1+Premissas!$C$26)^(1) -> 1.08 | E26: =Dimensionador!$C$22*(Premissas!$C$32+0.6666666667*(Premissas!$C$33-Premissas!$C$32))*Premissas!$C$21*(1+Premissas!$C$26)^(1) -> 14204.974 | F26: =Dimensionador!$C$23*(Premissas!$C$32+0.6666666667*(Premissas!$C$33-Premissas!$C$32))*Premissas!$C$20*(1+Premissas!$C$26)^(1) -> 689.80663 | G26: =Premissas!$C$25*(1+Premissas!$C$27)^(1)/12 -> 669.5 | H26: =E26-F26 -> 13515.167 | I26: =H26-G26 -> 12845.667 | J26: =J25+I26 -> -256166.94 | K26: =K25+I26 -> 263833.06 | L26: =IF(AND(J26>=0,J25<0),"✅ PAYBACK","") | M26: =I26 -> 12845.667
A27: 2 | B27: Out | C27: =Premissas!$C$32+0.75*(Premissas!$C$33-Premissas!$C$32) -> 0.95375 | D27: =(1+Premissas!$C$26)^(1) -> 1.08 | E27: =Dimensionador!$C$22*(Premissas!$C$32+0.75*(Premissas!$C$33-Premissas!$C$32))*Premissas!$C$21*(1+Premissas!$C$26)^(1) -> 14176.484 | F27: =Dimensionador!$C$23*(Premissas!$C$32+0.75*(Premissas!$C$33-Premissas!$C$32))*Premissas!$C$20*(1+Premissas!$C$26)^(1) -> 688.42316 | G27: =Premissas!$C$25*(1+Premissas!$C$27)^(1)/12 -> 669.5 | H27: =E27-F27 -> 13488.061 | I27: =H27-G27 -> 12818.561 | J27: =J26+I27 -> -243348.38 | K27: =K26+I27 -> 276651.62 | L27: =IF(AND(J27>=0,J26<0),"✅ PAYBACK","") | M27: =I27 -> 12818.561
A28: 2 | B28: Nov | C28: =Premissas!$C$32+0.8333333333*(Premissas!$C$33-Premissas!$C$32) -> 0.95183333 | D28: =(1+Premissas!$C$26)^(1) -> 1.08 | E28: =Dimensionador!$C$22*(Premissas!$C$32+0.8333333333*(Premissas!$C$33-Premissas!$C$32))*Premissas!$C$21*(1+Premissas!$C$26)^(1) -> 14147.995 | F28: =Dimensionador!$C$23*(Premissas!$C$32+0.8333333333*(Premissas!$C$33-Premissas!$C$32))*Premissas!$C$20*(1+Premissas!$C$26)^(1) -> 687.0397 | G28: =Premissas!$C$25*(1+Premissas!$C$27)^(1)/12 -> 669.5 | H28: =E28-F28 -> 13460.956 | I28: =H28-G28 -> 12791.456 | J28: =J27+I28 -> -230556.92 | K28: =K27+I28 -> 289443.08 | L28: =IF(AND(J28>=0,J27<0),"✅ PAYBACK","") | M28: =I28 -> 12791.456
A29: 2 | B29: Dez | C29: =Premissas!$C$32+0.9166666667*(Premissas!$C$33-Premissas!$C$32) -> 0.94991667 | D29: =(1+Premissas!$C$26)^(1) -> 1.08 | E29: =Dimensionador!$C$22*(Premissas!$C$32+0.9166666667*(Premissas!$C$33-Premissas!$C$32))*Premissas!$C$21*(1+Premissas!$C$26)^(1) -> 14119.506 | F29: =Dimensionador!$C$23*(Premissas!$C$32+0.9166666667*(Premissas!$C$33-Premissas!$C$32))*Premissas!$C$20*(1+Premissas!$C$26)^(1) -> 685.65624 | G29: =Premissas!$C$25*(1+Premissas!$C$27)^(1)/12 -> 669.5 | H29: =E29-F29 -> 13433.85 | I29: =H29-G29 -> 12764.35 | J29: =J28+I29 -> -217792.57 | K29: =K28+I29 -> 302207.43 | L29: =IF(AND(J29>=0,J28<0),"✅ PAYBACK","") | M29: =I29 -> 12764.35
A30: 3 | B30: Jan | C30: =Premissas!$C$33+0*(Premissas!$C$34-Premissas!$C$33) -> 0.948 | D30: =(1+Premissas!$C$26)^(2) -> 1.1664 | E30: =Dimensionador!$C$22*(Premissas!$C$33+0*(Premissas!$C$34-Premissas!$C$33))*Premissas!$C$21*(1+Premissas!$C$26)^(2) -> 15218.298 | F30: =Dimensionador!$C$23*(Premissas!$C$33+0*(Premissas!$C$34-Premissas!$C$33))*Premissas!$C$20*(1+Premissas!$C$26)^(2) -> 739.0146 | G30: =Premissas!$C$25*(1+Premissas!$C$27)^(2)/12 -> 689.585 | H30: =E30-F30 -> 14479.284 | I30: =H30-G30 -> 13789.699 | J30: =J29+I30 -> -204002.87 | K30: =K29+I30 -> 315997.13 | L30: =IF(AND(J30>=0,J29<0),"✅ PAYBACK","") | M30: =I30 -> 13789.699
A31: 3 | B31: Fev | C31: =Premissas!$C$33+0.0833333333*(Premissas!$C$34-Premissas!$C$33) -> 0.94625 | D31: =(1+Premissas!$C$26)^(2) -> 1.1664 | E31: =Dimensionador!$C$22*(Premissas!$C$33+0.0833333333*(Premissas!$C$34-Premissas!$C$33))*Premissas!$C$21*(1+Premissas!$C$26)^(2) -> 15190.205 | F31: =Dimensionador!$C$23*(Premissas!$C$33+0.0833333333*(Premissas!$C$34-Premissas!$C$33))*Premissas!$C$20*(1+Premissas!$C$26)^(2) -> 737.65038 | G31: =Premissas!$C$25*(1+Premissas!$C$27)^(2)/12 -> 689.585 | H31: =E31-F31 -> 14452.555 | I31: =H31-G31 -> 13762.97 | J31: =J30+I31 -> -190239.9 | K31: =K30+I31 -> 329760.1 | L31: =IF(AND(J31>=0,J30<0),"✅ PAYBACK","") | M31: =I31 -> 13762.97
A32: 3 | B32: Mar | C32: =Premissas!$C$33+0.1666666667*(Premissas!$C$34-Premissas!$C$33) -> 0.9445 | D32: =(1+Premissas!$C$26)^(2) -> 1.1664 | E32: =Dimensionador!$C$22*(Premissas!$C$33+0.1666666667*(Premissas!$C$34-Premissas!$C$33))*Premissas!$C$21*(1+Premissas!$C$26)^(2) -> 15162.112 | F32: =Dimensionador!$C$23*(Premissas!$C$33+0.1666666667*(Premissas!$C$34-Premissas!$C$33))*Premissas!$C$20*(1+Premissas!$C$26)^(2) -> 736.28617 | G32: =Premissas!$C$25*(1+Premissas!$C$27)^(2)/12 -> 689.585 | H32: =E32-F32 -> 14425.826 | I32: =H32-G32 -> 13736.241 | J32: =J31+I32 -> -176503.66 | K32: =K31+I32 -> 343496.34 | L32: =IF(AND(J32>=0,J31<0),"✅ PAYBACK","") | M32: =I32 -> 13736.241
A33: 3 | B33: Abr | C33: =Premissas!$C$33+0.25*(Premissas!$C$34-Premissas!$C$33) -> 0.94275 | D33: =(1+Premissas!$C$26)^(2) -> 1.1664 | E33: =Dimensionador!$C$22*(Premissas!$C$33+0.25*(Premissas!$C$34-Premissas!$C$33))*Premissas!$C$21*(1+Premissas!$C$26)^(2) -> 15134.02 | F33: =Dimensionador!$C$23*(Premissas!$C$33+0.25*(Premissas!$C$34-Premissas!$C$33))*Premissas!$C$20*(1+Premissas!$C$26)^(2) -> 734.92195 | G33: =Premissas!$C$25*(1+Premissas!$C$27)^(2)/12 -> 689.585 | H33: =E33-F33 -> 14399.098 | I33: =H33-G33 -> 13709.513 | J33: =J32+I33 -> -162794.15 | K33: =K32+I33 -> 357205.85 | L33: =IF(AND(J33>=0,J32<0),"✅ PAYBACK","") | M33: =I33 -> 13709.513
A34: 3 | B34: Mai | C34: =Premissas!$C$33+0.3333333333*(Premissas!$C$34-Premissas!$C$33) -> 0.941 | D34: =(1+Premissas!$C$26)^(2) -> 1.1664 | E34: =Dimensionador!$C$22*(Premissas!$C$33+0.3333333333*(Premissas!$C$34-Premissas!$C$33))*Premissas!$C$21*(1+Premissas!$C$26)^(2) -> 15105.927 | F34: =Dimensionador!$C$23*(Premissas!$C$33+0.3333333333*(Premissas!$C$34-Premissas!$C$33))*Premissas!$C$20*(1+Premissas!$C$26)^(2) -> 733.55774 | G34: =Premissas!$C$25*(1+Premissas!$C$27)^(2)/12 -> 689.585 | H34: =E34-F34 -> 14372.369 | I34: =H34-G34 -> 13682.784 | J34: =J33+I34 -> -149111.37 | K34: =K33+I34 -> 370888.63 | L34: =IF(AND(J34>=0,J33<0),"✅ PAYBACK","") | M34: =I34 -> 13682.784
A35: 3 | B35: Jun | C35: =Premissas!$C$33+0.4166666667*(Premissas!$C$34-Premissas!$C$33) -> 0.93925 | D35: =(1+Premissas!$C$26)^(2) -> 1.1664 | E35: =Dimensionador!$C$22*(Premissas!$C$33+0.4166666667*(Premissas!$C$34-Premissas!$C$33))*Premissas!$C$21*(1+Premissas!$C$26)^(2) -> 15077.834 | F35: =Dimensionador!$C$23*(Premissas!$C$33+0.4166666667*(Premissas!$C$34-Premissas!$C$33))*Premissas!$C$20*(1+Premissas!$C$26)^(2) -> 732.19352 | G35: =Premissas!$C$25*(1+Premissas!$C$27)^(2)/12 -> 689.585 | H35: =E35-F35 -> 14345.64 | I35: =H35-G35 -> 13656.055 | J35: =J34+I35 -> -135455.31 | K35: =K34+I35 -> 384544.69 | L35: =IF(AND(J35>=0,J34<0),"✅ PAYBACK","") | M35: =I35 -> 13656.055
A36: 3 | B36: Jul | C36: =Premissas!$C$33+0.5*(Premissas!$C$34-Premissas!$C$33) -> 0.9375 | D36: =(1+Premissas!$C$26)^(2) -> 1.1664 | E36: =Dimensionador!$C$22*(Premissas!$C$33+0.5*(Premissas!$C$34-Premissas!$C$33))*Premissas!$C$21*(1+Premissas!$C$26)^(2) -> 15049.741 | F36: =Dimensionador!$C$23*(Premissas!$C$33+0.5*(Premissas!$C$34-Premissas!$C$33))*Premissas!$C$20*(1+Premissas!$C$26)^(2) -> 730.82931 | G36: =Premissas!$C$25*(1+Premissas!$C$27)^(2)/12 -> 689.585 | H36: =E36-F36 -> 14318.912 | I36: =H36-G36 -> 13629.327 | J36: =J35+I36 -> -121825.98 | K36: =K35+I36 -> 398174.02 | L36: =IF(AND(J36>=0,J35<0),"✅ PAYBACK","") | M36: =I36 -> 13629.327
A37: 3 | B37: Ago | C37: =Premissas!$C$33+0.5833333333*(Premissas!$C$34-Premissas!$C$33) -> 0.93575 | D37: =(1+Premissas!$C$26)^(2) -> 1.1664 | E37: =Dimensionador!$C$22*(Premissas!$C$33+0.5833333333*(Premissas!$C$34-Premissas!$C$33))*Premissas!$C$21*(1+Premissas!$C$26)^(2) -> 15021.648 | F37: =Dimensionador!$C$23*(Premissas!$C$33+0.5833333333*(Premissas!$C$34-Premissas!$C$33))*Premissas!$C$20*(1+Premissas!$C$26)^(2) -> 729.46509 | G37: =Premissas!$C$25*(1+Premissas!$C$27)^(2)/12 -> 689.585 | H37: =E37-F37 -> 14292.183 | I37: =H37-G37 -> 13602.598 | J37: =J36+I37 -> -108223.39 | K37: =K36+I37 -> 411776.61 | L37: =IF(AND(J37>=0,J36<0),"✅ PAYBACK","") | M37: =I37 -> 13602.598
A38: 3 | B38: Set | C38: =Premissas!$C$33+0.6666666667*(Premissas!$C$34-Premissas!$C$33) -> 0.934 | D38: =(1+Premissas!$C$26)^(2) -> 1.1664 | E38: =Dimensionador!$C$22*(Premissas!$C$33+0.6666666667*(Premissas!$C$34-Premissas!$C$33))*Premissas!$C$21*(1+Premissas!$C$26)^(2) -> 14993.555 | F38: =Dimensionador!$C$23*(Premissas!$C$33+0.6666666667*(Premissas!$C$34-Premissas!$C$33))*Premissas!$C$20*(1+Premissas!$C$26)^(2) -> 728.10088 | G38: =Premissas!$C$25*(1+Premissas!$C$27)^(2)/12 -> 689.585 | H38: =E38-F38 -> 14265.454 | I38: =H38-G38 -> 13575.869 | J38: =J37+I38 -> -94647.516 | K38: =K37+I38 -> 425352.48 | L38: =IF(AND(J38>=0,J37<0),"✅ PAYBACK","") | M38: =I38 -> 13575.869
A39: 3 | B39: Out | C39: =Premissas!$C$33+0.75*(Premissas!$C$34-Premissas!$C$33) -> 0.93225 | D39: =(1+Premissas!$C$26)^(2) -> 1.1664 | E39: =Dimensionador!$C$22*(Premissas!$C$33+0.75*(Premissas!$C$34-Premissas!$C$33))*Premissas!$C$21*(1+Premissas!$C$26)^(2) -> 14965.462 | F39: =Dimensionador!$C$23*(Premissas!$C$33+0.75*(Premissas!$C$34-Premissas!$C$33))*Premissas!$C$20*(1+Premissas!$C$26)^(2) -> 726.73667 | G39: =Premissas!$C$25*(1+Premissas!$C$27)^(2)/12 -> 689.585 | H39: =E39-F39 -> 14238.726 | I39: =H39-G39 -> 13549.141 | J39: =J38+I39 -> -81098.376 | K39: =K38+I39 -> 438901.62 | L39: =IF(AND(J39>=0,J38<0),"✅ PAYBACK","") | M39: =I39 -> 13549.141
A40: 3 | B40: Nov | C40: =Premissas!$C$33+0.8333333333*(Premissas!$C$34-Premissas!$C$33) -> 0.9305 | D40: =(1+Premissas!$C$26)^(2) -> 1.1664 | E40: =Dimensionador!$C$22*(Premissas!$C$33+0.8333333333*(Premissas!$C$34-Premissas!$C$33))*Premissas!$C$21*(1+Premissas!$C$26)^(2) -> 14937.37 | F40: =Dimensionador!$C$23*(Premissas!$C$33+0.8333333333*(Premissas!$C$34-Premissas!$C$33))*Premissas!$C$20*(1+Premissas!$C$26)^(2) -> 725.37245 | G40: =Premissas!$C$25*(1+Premissas!$C$27)^(2)/12 -> 689.585 | H40: =E40-F40 -> 14211.997 | I40: =H40-G40 -> 13522.412 | J40: =J39+I40 -> -67575.963 | K40: =K39+I40 -> 452424.04 | L40: =IF(AND(J40>=0,J39<0),"✅ PAYBACK","") | M40: =I40 -> 13522.412
A41: 3 | B41: Dez | C41: =Premissas!$C$33+0.9166666667*(Premissas!$C$34-Premissas!$C$33) -> 0.92875 | D41: =(1+Premissas!$C$26)^(2) -> 1.1664 | E41: =Dimensionador!$C$22*(Premissas!$C$33+0.9166666667*(Premissas!$C$34-Premissas!$C$33))*Premissas!$C$21*(1+Premissas!$C$26)^(2) -> 14909.277 | F41: =Dimensionador!$C$23*(Premissas!$C$33+0.9166666667*(Premissas!$C$34-Premissas!$C$33))*Premissas!$C$20*(1+Premissas!$C$26)^(2) -> 724.00824 | G41: =Premissas!$C$25*(1+Premissas!$C$27)^(2)/12 -> 689.585 | H41: =E41-F41 -> 14185.269 | I41: =H41-G41 -> 13495.684 | J41: =J40+I41 -> -54080.28 | K41: =K40+I41 -> 465919.72 | L41: =IF(AND(J41>=0,J40<0),"✅ PAYBACK","") | M41: =I41 -> 13495.684
...

Sheet Premissas
A1: PREMISSAS — BESS LOAD SHIFTING
A2: Azul = input editável | Verde = calculado | Vinculado ao Dimensionador
B4: EQUIPAMENTO BESS | C4: VALOR | D4: UNIDADE
B5: Potência BESS | C5: 241 | D5: kW
B6: DoD | C6: 1 | D6: p.u. | F6: =C10*C11 -> 4692.1701 | G6: =Dimensionador!C5/F6 -> 0.50083436
B7: η BESS round-trip | C7: 0.9556 | D7: p.u.
B8: η Elétrica | C8: 0.98 | D8: p.u.
B9: η Operacional | C9: 0.99 | D9: p.u.
B10: Dias úteis/mês | C10: 21 | D10: dias
B11: Energia útil/ciclo [calc] | C11: =C5*C6*C7*C8*C9 -> 223.43667 | D11: kWh
B12: Energia útil/mês 1 BESS [calc] | C12: =C11*C10 -> 4692.1701 | D12: kWh
B13: Energia carga/mês 1 BESS [calc] | C13: =((C5*C10*C6)/(C7*C8*C9)) -> 5458.8219 | D13: kWh
B15: TARIFAS — MERCADO LIVRE | C15: VALOR | D15: UNIDADE
B16: TUSD Fora Ponta | C16: 0.12243293 | D16: R$/kWh
B17: TE Fora Ponta ML | C17: 0 | D17: R$/kWh
B18: TUSD Na Ponta | C18: 2.933165 | D18: R$/kWh
B19: TE Na Ponta ML | C19: 0 | D19: R$/kWh
B20: HFP Total [calc] | C20: =C16+C17 -> 0.12243293 | D20: R$/kWh
B21: HP Total [calc] | C21: =C18+C19 -> 2.933165 | D21: R$/kWh
B22: Delta HP-HFP [calc] | C22: =C21-C20 -> 2.810732 | D22: R$/kWh
B24: PARÂMETROS FINANCEIROS | C24: VALOR | D24: UNIDADE
B25: O&M por BESS/ano | C25: =Dimensionador!C8*1.5% -> 7800 | D25: R$/ano
B26: Reajuste energia | C26: 0.08 | D26: % a.a.
B27: Reajuste O&M | C27: 0.03 | D27: % a.a.
B28: TMA | C28: 0.12 | D28: % a.a.
B30: CURVA SOH HUAWEI (1 ciclo/dia, DoD 100%) | C30: SOH | D30: Ano | J30: 215 | K30: 241
B31: Ano 0 | C31: 1 | D31: 0 | J31: 1 | K31: =O31/1 -> 1 | O31: 1
B32: Ano 1 | C32: 0.971 | D32: 1 | J32: 0.93884 | K32: =O32/1 -> 0.971 | O32: 0.971
B33: Ano 2 | C33: 0.948 | D33: 2 | J33: 0.91336 | K33: =O33/1 -> 0.948 | O33: 0.948
B34: Ano 3 | C34: 0.927 | D34: 3 | J34: 0.89358 | K34: =O34/1 -> 0.927 | O34: 0.927
B35: Ano 4 | C35: 0.907 | D35: 4 | J35: 0.87591 | K35: =O35/1 -> 0.907 | O35: 0.907
B36: Ano 5 | C36: 0.888 | D36: 5 | J36: 0.85936 | K36: =O36/1 -> 0.888 | O36: 0.888
B37: Ano 6 | C37: 0.87 | D37: 6 | J37: 0.84357 | K37: =O37/1 -> 0.87 | O37: 0.87
B38: Ano 7 | C38: 0.852 | D38: 7 | J38: 0.82835 | K38: =O38/1 -> 0.852 | O38: 0.852
B39: Ano 8 | C39: 0.834 | D39: 8 | J39: 0.81357 | K39: =O39/1 -> 0.834 | O39: 0.834
B40: Ano 9 | C40: 0.817 | D40: 9 | J40: 0.79916 | K40: =O40/1 -> 0.817 | O40: 0.817
B41: Ano 10 | C41: 0.799 | D41: 10 | J41: 0.78506 | K41: =O41/1 -> 0.799 | O41: 0.799
B42: Ano 11 | C42: 0.783 | D42: 11 | J42: 0.77122 | K42: =O42/1 -> 0.783 | O42: 0.783
... B51: Ano 20 | C51: 0.645 | D51: 20 | J51: 0.65454 | K51: =O51/1 -> 0.645 | O51: 0.645
