Workbook

Sheet Dimensionador
A1: DIMENSIONADOR DE BESS — LOAD SHIFTING
A2: Preencha as células em AZUL. A planilha calcula o número sugerido e todos os indicadores.
A4: ① ENTRADA: CONSUMO E DIMENSIONAMENTO
B5: Consumo médio de ponta desejado | C5: 6900 | D5: kWh/mês | E5: Média mensal de energia a deslocar do HP para HFP
B6: ⟹ Nº sugerido de BESS (calculado) | C6: =CEILING(C5/(Premissas!$C$12),1) -> 2 | D6: unidades | E6: Arredondamento para cima (energia útil 1 BESS = C12 da aba Premissas)
B7: ✏️ Nº de BESS adotado (você define) | C7: 2 | D7: unidades | E7: ⬅ EDITE AQUI: confirme ou altere o número sugerido acima
B8: CAPEX total negociado (todos os BESS) | C8: 1100000 | D8: R$ | E8: Valor total com instalação, frete e comissionamento
A10: ② PARÂMETROS DO EQUIPAMENTO (vinculados à aba Premissas)
B11: Potência nominal | C11: =Premissas!C5 -> 241 | D11: kW
B12: DoD | C12: =Premissas!C6 -> 1 | D12: p.u.
B13: η BESS round-trip | C13: =Premissas!C7 -> 0.9556 | D13: p.u.
B14: η Elétrica | C14: =Premissas!C8 -> 0.98 | D14: p.u.
B15: η Operacional | C15: =Premissas!C9 -> 0.99 | D15: p.u.
B16: Dias úteis/mês | C16: =Premissas!C10 -> 21 | D16: dias
B17: Energia útil/ciclo | C17: =Premissas!C11 -> 223.43667 | D17: kWh/ciclo
B18: Energia útil/mês 1 BESS | C18: =Premissas!C12 -> 3450.0001 | D18: kWh/mês
B19: Energia carga/mês 1 BESS | C19: =Premissas!C13 -> 4013.6942 | D19: kWh/mês
A21: ③ ENERGIA CALCULADA COM O Nº DE BESS ADOTADO
B22: Energia útil/mês (N BESS) | C22: =$C$7*Premissas!$C$12 -> 6900.0002 | E22: N BESS × energia útil 1 BESS
B23: Energia carga/mês (N BESS) | C23: =$C$7*Premissas!$C$13 -> 8027.3884 | E23: N BESS × energia de carga 1 BESS
B24: Cobertura do consumo desejado | C24: =C22/C5 -> 1 | E24: Energia disponível ÷ consumo de ponta médio
B25: Receita HP ano 1 (base) | C25: =C22*Premissas!$C$21*12 -> 222663.7 | E25: Energia útil × tarifa HP × 12 meses
B26: Custo HFP ano 1 (base) | C26: =C23*Premissas!$C$20*12 -> 60298.081 | E26: Energia de carga × tarifa HFP × 12 meses
B27: Economia bruta ano 1 (base) | C27: =C25-C26 -> 162365.61 | E27: Receita HP − Custo HFP (sem degradação)
B28: O&M ano 1 (N BESS) | C28: =$C$7*Premissas!$C$25 -> 22000 | E28: N BESS × O&M unitário
B29: Economia líquida ano 1 (base) | C29: =C27-C28 -> 140365.61 | E29: Após O&M, sem degradação ainda
A31: ④ TARIFAS (vinculadas à aba Premissas)
B32: Tarifa HFP total | C32: =Premissas!$C$20 -> 0.625962
B33: Tarifa HP total | C33: =Premissas!$C$21 -> 2.689175
B34: Delta HP − HFP | C34: =Premissas!$C$22 -> 2.063213
B35: Reajuste tarifário anual | C35: =Premissas!$C$26 -> 0.08
A36: ⑥ SISTEMA SOLAR — DIMENSIONAMENTO E ENERGIA
B37: Potência solar instalada | C37: =Premissas!$C$30 -> 475 | E37: Vinculado às Premissas
B38: Performance Ratio (PR) | C38: =Premissas!$C$31 -> 0.75 | E38: Vinculado às Premissas
B39: CAPEX solar total | C39: =Premissas!$C$33 -> 1187500 | E39: Vinculado às Premissas
B40: O&M solar ano 1 | C40: =Premissas!$C$35 -> 11875 | E40: CAPEX solar × % O&M
B41: Geração solar média/mês | C41: =Premissas!$C$65 -> 54179.688 | E41: Média dos 12 meses
B42: Acumulado Ano 20 | C42: ='Fluxo 20 Anos'!C253 -> 20025677
A43: ALOCAÇÃO DA GERAÇÃO SOLAR (mês médio)
B44: Energia necessária p/ carga BESS/mês | C44: =$C$7*Premissas!$C$13 -> 8027.3884 | E44: N BESS × energia de carga 1 BESS
...

Sheet Fluxo 20 Anos
A1: FLUXO DE CAIXA — MÊS A MÊS — 20 ANOS | N BESS DINÂMICO
A2: SOH interpolado mensalmente | Reajuste tarifário anual | Degradação contínua ao longo dos 240 meses
A4: Ano | B4: Mês | C4: SOH Mês | D4: Reajuste Tarifário | E4: Receita HP (R$) | F4: Custo HFP (R$) | G4: O&M (R$/mês) | H4: Geração Solar (kWh) | I4: Solar→ BESS (kWh) | J4: Solar→ Exced. (kWh) | K4: O&M Solar (R$/mês) | L4: Eco. Bruta (R$/mês) | M4: Eco. Líq. (R$/mês) | N4: Acumulado (R$) | O4: Eco. Acum. (sem CAPEX) | P4: Payback
A5: 0 | B5: Invest. | M5: =-Dimensionador!$C$8 -> -1100000 | N5: =-(Dimensionador!$C$8+Premissas!$C$33) -> -2287500 | O5: =0 -> 0 | Q5: =-(Dimensionador!$C$8+Premissas!$C$33) -> -2287500 | R5: =-Dimensionador!$C$8 -> -1100000
A6: 1 | B6: Jan | C6: =Premissas!$C$69+0*(Premissas!$C$70-Premissas!$C$69) -> 1 | D6: =(1+Premissas!$C$26)^(0) -> 1 | E6: =Dimensionador!$C$22*(Premissas!$C$69+0*(Premissas!$C$70-Premissas!$C$69))*Premissas!$C$21*(1+Premissas!$C$26)^(0) -> 18555.308 | F6: =Dimensionador!$C$7*Premissas!$C$13*(Premissas!$C$69+0*(Premissas!$C$70-Premissas!$C$69))*Premissas!$C$20*(1+Premissas!$C$26)^(0) -> 5024.8401 | G6: =Dimensionador!$C$7*Premissas!$C$25*(1+Premissas!$C$27)^(0)/12 -> 1833.3333 | H6: =Premissas!$C$52*(1-Premissas!$C$32)^(0) -> 55218.75 | I6: =MIN(H6,Dimensionador!$C$7*Premissas!$C$13*(Premissas!$C$69+0*(Premissas!$C$70-Premissas!$C$69))) -> 8027.3884 | J6: =MAX(0,H6-I6) -> 47191.362 | K6: =Premissas!$C$35*(1+Premissas!$C$27)^(0)/12 -> 989.58333 | L6: =E6-F6+(I6+J6)*Premissas!$C$20*(1+Premissas!$C$26)^(0) -> 48095.307 | M6: =L6-G6-K6 -> 45272.39 | N6: =N5+M6 -> -2242227.6 | O6: =M6 -> 45272.39 | P6: "" | Q6: =SUM(M6:M17) -> 533305.61 | R6: =SUM(I6:I17) -> 95048.293
A7: 1 | B7: Fev | C7: =Premissas!$C$69+0.0833333333*(Premissas!$C$70-Premissas!$C$69) -> 0.99758333 | D7: =(1+Premissas!$C$26)^(0) -> 1 | E7: =Dimensionador!$C$22*(Premissas!$C$69+0.0833333333*(Premissas!$C$70-Premissas!$C$69))*Premissas!$C$21*(1+Premissas!$C$26)^(0) -> 18510.466 | F7: =Dimensionador!$C$7*Premissas!$C$13*(Premissas!$C$69+0.0833333333*(Premissas!$C$70-Premissas!$C$69))*Premissas!$C$20*(1+Premissas!$C$26)^(0) -> 5012.6968 | G7: =Dimensionador!$C$7*Premissas!$C$25*(1+Premissas!$C$27)^(0)/12 -> 1833.3333 | H7: =Premissas!$C$53*(1-Premissas!$C$32)^(0) -> 49875 | I7: =MIN(H7,Dimensionador!$C$7*Premissas!$C$13*(Premissas!$C$69+0.0833333333*(Premissas!$C$70-Premissas!$C$69))) -> 8007.9889 | J7: =MAX(0,H7-I7) -> 41867.011 | K7: =Premissas!$C$35*(1+Premissas!$C$27)^(0)/12 -> 989.58333 | L7: =E7-F7+(I7+J7)*Premissas!$C$20*(1+Premissas!$C$26)^(0) -> 44717.624 | M7: =L7-G7-K7 -> 41894.707 | N7: =N6+M7 -> -2200332.9 | O7: =O6+M7 -> 87167.098 | P7: =IF(AND(N7>=0,N6<0),"✅ PAYBACK","") | Q7: =SUM(M18:M29) -> 570863.09 | R7: =SUM(I18:I29) -> 92519.665
A8: 1 | B8: Mar | C8: =Premissas!$C$69+0.1666666667*(Premissas!$C$70-Premissas!$C$69) -> 0.99516667 | D8: =(1+Premissas!$C$26)^(0) -> 1 | E8: =Dimensionador!$C$22*(Premissas!$C$69+0.1666666667*(Premissas!$C$70-Premissas!$C$69))*Premissas!$C$21*(1+Premissas!$C$26)^(0) -> 18465.624 | F8: =Dimensionador!$C$7*Premissas!$C$13*(Premissas!$C$69+0.1666666667*(Premissas!$C$70-Premissas!$C$69))*Premissas!$C$20*(1+Premissas!$C$26)^(0) -> 5000.5534 | G8: =Dimensionador!$C$7*Premissas!$C$25*(1+Premissas!$C$27)^(0)/12 -> 1833.3333 | H8: =Premissas!$C$54*(1-Premissas!$C$32)^(0) -> 55218.75 | I8: =MIN(H8,Dimensionador!$C$7*Premissas!$C$13*(Premissas!$C$69+0.1666666667*(Premissas!$C$70-Premissas!$C$69))) -> 7988.5894 | J8: =MAX(0,H8-I8) -> 47230.161 | K8: =Premissas!$C$35*(1+Premissas!$C$27)^(0)/12 -> 989.58333 | L8: =E8-F8+(I8+J8)*Premissas!$C$20*(1+Premissas!$C$26)^(0) -> 48029.91 | M8: =L8-G8-K8 -> 45206.993 | N8: =N7+M8 -> -2155125.9 | O8: =O7+M8 -> 132374.09 | P8: =IF(AND(N8>=0,N7<0),"✅ PAYBACK","") | Q8: =SUM(M30:M41) -> 611732.89 | R8: =SUM(I30:I41) -> 90392.407
A9: 1 | B9: Abr | C9: =Premissas!$C$69+0.25*(Premissas!$C$70-Premissas!$C$69) -> 0.99275 | D9: =(1+Premissas!$C$26)^(0) -> 1 | E9: =Dimensionador!$C$22*(Premissas!$C$69+0.25*(Premissas!$C$70-Premissas!$C$69))*Premissas!$C$21*(1+Premissas!$C$26)^(0) -> 18420.782 | F9: =Dimensionador!$C$7*Premissas!$C$13*(Premissas!$C$69+0.25*(Premissas!$C$70-Premissas!$C$69))*Premissas!$C$20*(1+Premissas!$C$26)^(0) -> 4988.41 | G9: =Dimensionador!$C$7*Premissas!$C$25*(1+Premissas!$C$27)^(0)/12 -> 1833.3333 | H9: =Premissas!$C$55*(1-Premissas!$C$32)^(0) -> 53437.5 | I9: =MIN(H9,Dimensionador!$C$7*Premissas!$C$13*(Premissas!$C$69+0.25*(Premissas!$C$70-Premissas!$C$69))) -> 7969.1899 | J9: =MAX(0,H9-I9) -> 45468.31 | K9: =Premissas!$C$35*(1+Premissas!$C$27)^(0)/12 -> 989.58333 | L9: =E9-F9+(I9+J9)*Premissas!$C$20*(1+Premissas!$C$26)^(0) -> 46882.216 | M9: =L9-G9-K9 -> 44059.3 | N9: =N8+M9 -> -2111066.6 | O9: =O8+M9 -> 176433.39 | P9: =IF(AND(N9>=0,N8<0),"✅ PAYBACK","") | Q9: =SUM(M42:M53) -> 655729.17 | R9: =SUM(I42:I53) -> 88413.656
A10: 1 | B10: Mai | C10: =Premissas!$C$69+0.3333333333*(Premissas!$C$70-Premissas!$C$69) -> 0.99033333 | D10: =(1+Premissas!$C$26)^(0) -> 1 | E10: =Dimensionador!$C$22*(Premissas!$C$69+0.3333333333*(Premissas!$C$70-Premissas!$C$69))*Premissas!$C$21*(1+Premissas!$C$26)^(0) -> 18375.94 | F10: =Dimensionador!$C$7*Premissas!$C$13*(Premissas!$C$69+0.3333333333*(Premissas!$C$70-Premissas!$C$69))*Premissas!$C$20*(1+Premissas!$C$26)^(0) -> 4976.2667 | G10: =Dimensionador!$C$7*Premissas!$C$25*(1+Premissas!$C$27)^(0)/12 -> 1833.3333 | H10: =Premissas!$C$56*(1-Premissas!$C$32)^(0) -> 55218.75 | I10: =MIN(H10,Dimensionador!$C$7*Premissas!$C$13*(Premissas!$C$69+0.3333333333*(Premissas!$C$70-Premissas!$C$69))) -> 7949.7903 | J10: =MAX(0,H10-I10) -> 47268.96 | K10: =Premissas!$C$35*(1+Premissas!$C$27)^(0)/12 -> 989.58333 | L10: =E10-F10+(I10+J10)*Premissas!$C$20*(1+Premissas!$C$26)^(0) -> 47964.512 | M10: =L10-G10-K10 -> 45141.596 | N10: =N9+M10 -> -2065925 | O10: =O9+M10 -> 221574.99 | P10: =IF(AND(N10>=0,N9<0),"✅ PAYBACK","") | Q10: =SUM(M54:M65) -> 702994.53 | R10: =SUM(I54:I65) -> 86531.234
A11: 1 | B11: Jun | C11: =Premissas!$C$69+0.4166666667*(Premissas!$C$70-Premissas!$C$69) -> 0.98791667 | D11: =(1+Premissas!$C$26)^(0) -> 1 | E11: =Dimensionador!$C$22*(Premissas!$C$69+0.4166666667*(Premissas!$C$70-Premissas!$C$69))*Premissas!$C$21*(1+Premissas!$C$26)^(0) -> 18331.098 | F11: =Dimensionador!$C$7*Premissas!$C$13*(Premissas!$C$69+0.4166666667*(Premissas!$C$70-Premissas!$C$69))*Premissas!$C$20*(1+Premissas!$C$26)^(0) -> 4964.1233 | G11: =Dimensionador!$C$7*Premissas!$C$25*(1+Premissas!$C$27)^(0)/12 -> 1833.3333 | H11: =Premissas!$C$57*(1-Premissas!$C$32)^(0) -> 53437.5 | I11: =MIN(H11,Dimensionador!$C$7*Premissas!$C$13*(Premissas!$C$69+0.4166666667*(Premissas!$C$70-Premissas!$C$69))) -> 7930.3908 | J11: =MAX(0,H11-I11) -> 45507.109 | K11: =Premissas!$C$35*(1+Premissas!$C$27)^(0)/12 -> 989.58333 | L11: =E11-F11+(I11+J11)*Premissas!$C$20*(1+Premissas!$C$26)^(0) -> 46816.819 | M11: =L11-G11-K11 -> 43993.902 | N11: =N10+M11 -> -2021931.1 | O11: =O10+M11 -> 265568.89 | P11: =IF(AND(N11>=0,N10<0),"✅ PAYBACK","") | Q11: =SUM(M66:M77) -> 753786.44 | R11: =SUM(I66:I77) -> 84745.14
A12: 1 | B12: Jul | C12: =Premissas!$C$69+0.5*(Premissas!$C$70-Premissas!$C$69) -> 0.9855 | D12: =(1+Premissas!$C$26)^(0) -> 1 | E12: =Dimensionador!$C$22*(Premissas!$C$69+0.5*(Premissas!$C$70-Premissas!$C$69))*Premissas!$C$21*(1+Premissas!$C$26)^(0) -> 18286.256 | F12: =Dimensionador!$C$7*Premissas!$C$13*(Premissas!$C$69+0.5*(Premissas!$C$70-Premissas!$C$69))*Premissas!$C$20*(1+Premissas!$C$26)^(0) -> 4951.9799 | G12: =Dimensionador!$C$7*Premissas!$C$25*(1+Premissas!$C$27)^(0)/12 -> 1833.3333 | H12: =Premissas!$C$58*(1-Premissas!$C$32)^(0) -> 55218.75 | I12: =MIN(H12,Dimensionador!$C$7*Premissas!$C$13*(Premissas!$C$69+0.5*(Premissas!$C$70-Premissas!$C$69))) -> 7910.9913 | J12: =MAX(0,H12-I12) -> 47307.759 | K12: =Premissas!$C$35*(1+Premissas!$C$27)^(0)/12 -> 989.58333 | L12: =E12-F12+(I12+J12)*Premissas!$C$20*(1+Premissas!$C$26)^(0) -> 47899.115 | M12: =L12-G12-K12 -> 45076.199 | N12: =N11+M12 -> -1976854.9 | O12: =O11+M12 -> 310645.09 | P12: =IF(AND(N12>=0,N11<0),"✅ PAYBACK","") | Q12: =SUM(M78:M89) -> 808265.95 | R12: =SUM(I78:I89) -> 83011.224
A13: 1 | B13: Ago | C13: =Premissas!$C$69+0.5833333333*(Premissas!$C$70-Premissas!$C$69) -> 0.98308333 | D13: =(1+Premissas!$C$26)^(0) -> 1 | E13: =Dimensionador!$C$22*(Premissas!$C$69+0.5833333333*(Premissas!$C$70-Premissas!$C$69))*Premissas!$C$21*(1+Premissas!$C$26)^(0) -> 18241.414 | F13: =Dimensionador!$C$7*Premissas!$C$13*(Premissas!$C$69+0.5833333333*(Premissas!$C$70-Premissas!$C$69))*Premissas!$C$20*(1+Premissas!$C$26)^(0) -> 4939.8366 | G13: =Dimensionador!$C$7*Premissas!$C$25*(1+Premissas!$C$27)^(0)/12 -> 1833.3333 | H13: =Premissas!$C$59*(1-Premissas!$C$32)^(0) -> 55218.75 | I13: =MIN(H13,Dimensionador!$C$7*Premissas!$C$13*(Premissas!$C$69+0.5833333333*(Premissas!$C$70-Premissas!$C$69))) -> 7891.5918 | J13: =MAX(0,H13-I13) -> 47327.158 | K13: =Premissas!$C$35*(1+Premissas!$C$27)^(0)/12 -> 989.58333 | L13: =E13-F13+(I13+J13)*Premissas!$C$20*(1+Premissas!$C$26)^(0) -> 47866.417 | M13: =L13-G13-K13 -> 45043.5 | N13: =N12+M13 -> -1931811.4 | O13: =O12+M13 -> 355688.59 | P13: =IF(AND(N13>=0,N12<0),"✅ PAYBACK","") | Q13: =SUM(M90:M101) -> 866556.78 | R13: =SUM(I90:I101) -> 81277.308
A14: 1 | B14: Set | C14: =Premissas!$C$69+0.6666666667*(Premissas!$C$70-Premissas!$C$69) -> 0.98066667 | D14: =(1+Premissas!$C$26)^(0) -> 1 | E14: =Dimensionador!$C$22*(Premissas!$C$69+0.6666666667*(Premissas!$C$70-Premissas!$C$69))*Premissas!$C$21*(1+Premissas!$C$26)^(0) -> 18196.572 | F14: =Dimensionador!$C$7*Premissas!$C$13*(Premissas!$C$69+0.6666666667*(Premissas!$C$70-Premissas!$C$69))*Premissas!$C$20*(1+Premissas!$C$26)^(0) -> 4927.6932 | G14: =Dimensionador!$C$7*Premissas!$C$25*(1+Premissas!$C$27)^(0)/12 -> 1833.3333 | H14: =Premissas!$C$60*(1-Premissas!$C$32)^(0) -> 53437.5 | I14: =MIN(H14,Dimensionador!$C$7*Premissas!$C$13*(Premissas!$C$69+0.6666666667*(Premissas!$C$70-Premissas!$C$69))) -> 7872.1923 | J14: =MAX(0,H14-I14) -> 45565.308 | K14: =Premissas!$C$35*(1+Premissas!$C$27)^(0)/12 -> 989.58333 | L14: =E14-F14+(I14+J14)*Premissas!$C$20*(1+Premissas!$C$26)^(0) -> 46718.723 | M14: =L14-G14-K14 -> 43895.806 | N14: =N13+M14 -> -1887915.6 | O14: =O13+M14 -> 399584.39 | P14: =IF(AND(N14>=0,N13<0),"✅ PAYBACK","") | Q14: =SUM(M102:M113) -> 929056.14 | R14: =SUM(I102:I113) -> 79587.543
A15: 1 | B15: Out | C15: =Premissas!$C$69+0.75*(Premissas!$C$70-Premissas!$C$69) -> 0.97825 | D15: =(1+Premissas!$C$26)^(0) -> 1 | E15: =Dimensionador!$C$22*(Premissas!$C$69+0.75*(Premissas!$C$70-Premissas!$C$69))*Premissas!$C$21*(1+Premissas!$C$26)^(0) -> 18151.73 | F15: =Dimensionador!$C$7*Premissas!$C$13*(Premissas!$C$69+0.75*(Premissas!$C$70-Premissas!$C$69))*Premissas!$C$20*(1+Premissas!$C$26)^(0) -> 4915.5498 | G15: =Dimensionador!$C$7*Premissas!$C$25*(1+Premissas!$C$27)^(0)/12 -> 1833.3333 | H15: =Premissas!$C$61*(1-Premissas!$C$32)^(0) -> 55218.75 | I15: =MIN(H15,Dimensionador!$C$7*Premissas!$C$13*(Premissas!$C$69+0.75*(Premissas!$C$70-Premissas!$C$69))) -> 7852.7927 | J15: =MAX(0,H15-I15) -> 47365.957 | K15: =Premissas!$C$35*(1+Premissas!$C$27)^(0)/12 -> 989.58333 | L15: =E15-F15+(I15+J15)*Premissas!$C$20*(1+Premissas!$C$26)^(0) -> 47801.019 | M15: =L15-G15-K15 -> 44978.103 | N15: =N14+M15 -> -1842937.5 | O15: =O14+M15 -> 444562.5 | P15: =IF(AND(N15>=0,N14<0),"✅ PAYBACK","") | Q15: =SUM(M114:M125) -> 995951.96 | R15: =SUM(I114:I125) -> 77905.805
A16: 1 | B16: Nov | C16: =Premissas!$C$69+0.8333333333*(Premissas!$C$70-Premissas!$C$69) -> 0.97583333 | D16: =(1+Premissas!$C$26)^(0) -> 1 | E16: =Dimensionador!$C$22*(Premissas!$C$69+0.8333333333*(Premissas!$C$70-Premissas!$C$69))*Premissas!$C$21*(1+Premissas!$C$26)^(0) -> 18106.888 | F16: =Dimensionador!$C$7*Premissas!$C$13*(Premissas!$C$69+0.8333333333*(Premissas!$C$70-Premissas!$C$69))*Premissas!$C$20*(1+Premissas!$C$26)^(0) -> 4903.4065 | G16: =Dimensionador!$C$7*Premissas!$C$25*(1+Premissas!$C$27)^(0)/12 -> 1833.3333 | H16: =Premissas!$C$62*(1-Premissas!$C$32)^(0) -> 53437.5 | I16: =MIN(H16,Dimensionador!$C$7*Premissas!$C$13*(Premissas!$C$69+0.8333333333*(Premissas!$C$70-Premissas!$C$69))) -> 7833.3932 | J16: =MAX(0,H16-I16) -> 45604.107 | K16: =Premissas!$C$35*(1+Premissas!$C$27)^(0)/12 -> 989.58333 | L16: =E16-F16+(I16+J16)*Premissas!$C$20*(1+Premissas!$C$26)^(0) -> 46653.326 | M16: =L16-G16-K16 -> 43830.409 | N16: =N15+M16 -> -1799107.1 | O16: =O15+M16 -> 488392.91 | P16: =IF(AND(N16>=0,N15<0),"✅ PAYBACK","") | Q16: =SUM(M126:M137) -> 1067650.4 | R16: =SUM(I126:I137) -> 76260.19
A17: 1 | B17: Dez | C17: =Premissas!$C$69+0.9166666667*(Premissas!$C$70-Premissas!$C$69) -> 0.97341667 | D17: =(1+Premissas!$C$26)^(0) -> 1 | E17: =Dimensionador!$C$22*(Premissas!$C$69+0.9166666667*(Premissas!$C$70-Premissas!$C$69))*Premissas!$C$21*(1+Premissas!$C$26)^(0) -> 18062.046 | F17: =Dimensionador!$C$7*Premissas!$C$13*(Premissas!$C$69+0.9166666667*(Premissas!$C$70-Premissas!$C$69))*Premissas!$C$20*(1+Premissas!$C$26)^(0) -> 4891.2631 | G17: =Dimensionador!$C$7*Premissas!$C$25*(1+Premissas!$C$27)^(0)/12 -> 1833.3333 | H17: =Premissas!$C$63*(1-Premissas!$C$32)^(0) -> 55218.75 | I17: =MIN(H17,Dimensionador!$C$7*Premissas!$C$13*(Premissas!$C$69+0.9166666667*(Premissas!$C$70-Premissas!$C$69))) -> 7813.9937 | J17: =MAX(0,H17-I17) -> 47404.756 | K17: =Premissas!$C$35*(1+Premissas!$C$27)^(0)/12 -> 989.58333 | L17: =E17-F17+(I17+J17)*Premissas!$C$20*(1+Premissas!$C$26)^(0) -> 47735.622 | M17: =L17-G17-K17 -> 44912.705 | N17: =N16+M17 -> -1754194.4 | O17: =O16+M17 -> 533305.61 | P17: =IF(AND(N17>=0,N16<0),"✅ PAYBACK","") | Q17: =SUM(M138:M149) -> 1144074.8 | R17: =SUM(I138:I149) -> 74542.329
A18: 2 | B18: Jan | C18: =Premissas!$C$70+0*(Premissas!$C$71-Premissas!$C$70) -> 0.971 | D18: =(1+Premissas!$C$26)^(1) -> 1.08 | E18: =Dimensionador!$C$22*(Premissas!$C$70+0*(Premissas!$C$71-Premissas!$C$70))*Premissas!$C$21*(1+Premissas!$C$26)^(1) -> 19458.58 | F18: =Dimensionador!$C$7*Premissas!$C$13*(Premissas!$C$70+0*(Premissas!$C$71-Premissas!$C$70))*Premissas!$C$20*(1+Premissas!$C$26)^(1) -> 5269.4493 | G18: =Dimensionador!$C$7*Premissas!$C$25*(1+Premissas!$C$27)^(1)/12 -> 1888.3333 | H18: =Premissas!$C$52*(1-Premissas!$C$32)^(1) -> 54942.656 | I18: =MIN(H18,Dimensionador!$C$7*Premissas!$C$13*(Premissas!$C$70+0*(Premissas!$C$71-Premissas!$C$70))) -> 7794.5942 | J18: =MAX(0,H18-I18) -> 47148.062 | K18: =Premissas!$C$35*(1+Premissas!$C$27)^(1)/12 -> 1019.2708 | L18: =E18-F18+(I18+J18)*Premissas!$C$20*(1+Premissas!$C$26)^(1) -> 51332.507 | M18: =L18-G18-K18 -> 48424.903 | N18: =N17+M18 -> -1705769.5 | O18: =O17+M18 -> 581730.51 | P18: =IF(AND(N18>=0,N17<0),"✅ PAYBACK","") | Q18: =SUM(M150:M161) -> 1226230.6 | R18: =SUM(I150:I161) -> 72924.81
A19: 2 | B19: Fev | C19: =Premissas!$C$70+0.0833333333*(Premissas!$C$71-Premissas!$C$70) -> 0.96908333 | D19: =(1+Premissas!$C$26)^(1) -> 1.08 | E19: =Dimensionador!$C$22*(Premissas!$C$70+0.0833333333*(Premissas!$C$71-Premissas!$C$70))*Premissas!$C$21*(1+Premissas!$C$26)^(1) -> 19420.171 | F19: =Dimensionador!$C$7*Premissas!$C$13*(Premissas!$C$70+0.0833333333*(Premissas!$C$71-Premissas!$C$70))*Premissas!$C$20*(1+Premissas!$C$26)^(1) -> 5259.0479 | G19: =Dimensionador!$C$7*Premissas!$C$25*(1+Premissas!$C$27)^(1)/12 -> 1888.3333 | H19: =Premissas!$C$53*(1-Premissas!$C$32)^(1) -> 49625.625 | I19: =MIN(H19,Dimensionador!$C$7*Premissas!$C$13*(Premissas!$C$70+0.0833333333*(Premissas!$C$71-Premissas!$C$70))) -> 7779.2083 | J19: =MAX(0,H19-I19) -> 41846.417 | K19: =Premissas!$C$35*(1+Premissas!$C$27)^(1)/12 -> 1019.2708 | L19: =E19-F19+(I19+J19)*Premissas!$C$20*(1+Premissas!$C$26)^(1) -> 47709.979 | M19: =L19-G19-K19 -> 44802.375 | N19: =N18+M19 -> -1660967.1 | O19: =O18+M19 -> 626532.89 | P19: =IF(AND(N19>=0,N18<0),"✅ PAYBACK","") | Q19: =SUM(M162:M173) -> 1315185.3 | R19: =SUM(I162:I173) -> 71540.086
A20: 2 | B20: Mar | C20: =Premissas!$C$70+0.1666666667*(Premissas!$C$71-Premissas!$C$70) -> 0.96716667 | D20: =(1+Premissas!$C$26)^(1) -> 1.08 | E20: =Dimensionador!$C$22*(Premissas!$C$70+0.1666666667*(Premissas!$C$71-Premissas!$C$70))*Premissas!$C$21*(1+Premissas!$C$26)^(1) -> 19381.761 | F20: =Dimensionador!$C$7*Premissas!$C$13*(Premissas!$C$70+0.1666666667*(Premissas!$C$71-Premissas!$C$70))*Premissas!$C$20*(1+Premissas!$C$26)^(1) -> 5248.6465 | G20: =Dimensionador!$C$7*Premissas!$C$25*(1+Premissas!$C$27)^(1)/12 -> 1888.3333 | H20: =Premissas!$C$54*(1-Premissas!$C$32)^(1) -> 54942.656 | I20: =MIN(H20,Dimensionador!$C$7*Premissas!$C$13*(Premissas!$C$70+0.1666666667*(Premissas!$C$71-Premissas!$C$70))) -> 7763.8225 | J20: =MAX(0,H20-I20) -> 47178.834 | K20: =Premissas!$C$35*(1+Premissas!$C$27)^(1)/12 -> 1019.2708 | L20: =E20-F20+(I20+J20)*Premissas!$C$20*(1+Premissas!$C$26)^(1) -> 51276.491 | M20: =L20-G20-K20 -> 48368.887 | N20: =N19+M20 -> -1612598.2 | O20: =O19+M20 -> 674901.78 | P20: =IF(AND(N20>=0,N19<0),"✅ PAYBACK","") | Q20: =SUM(M174:M185) -> 1409657.3 | R20: =SUM(I174:I185) -> 69998.827
A21: 2 | B21: Abr | C21: =Premissas!$C$70+0.25*(Premissas!$C$71-Premissas!$C$70) -> 0.96525 | D21: =(1+Premissas!$C$26)^(1) -> 1.08 | E21: =Dimensionador!$C$22*(Premissas!$C$70+0.25*(Premissas!$C$71-Premissas!$C$70))*Premissas!$C$21*(1+Premissas!$C$26)^(1) -> 19343.352 | F21: =Dimensionador!$C$7*Premissas!$C$13*(Premissas!$C$70+0.25*(Premissas!$C$71-Premissas!$C$70))*Premissas!$C$20*(1+Premissas!$C$26)^(1) -> 5238.2451 | G21: =Dimensionador!$C$7*Premissas!$C$25*(1+Premissas!$C$27)^(1)/12 -> 1888.3333 | H21: =Premissas!$C$55*(1-Premissas!$C$32)^(1) -> 53170.312 | I21: =MIN(H21,Dimensionador!$C$7*Premissas!$C$13*(Premissas!$C$70+0.25*(Premissas!$C$71-Premissas!$C$70))) -> 7748.4367 | J21: =MAX(0,H21-I21) -> 45421.876 | K21: =Premissas!$C$35*(1+Premissas!$C$27)^(1)/12 -> 1019.2708 | L21: =E21-F21+(I21+J21)*Premissas!$C$20*(1+Premissas!$C$26)^(1) -> 50050.31 | M21: =L21-G21-K21 -> 47142.705 | N21: =N20+M21 -> -1565455.5 | O21: =O20+M21 -> 722044.48 | P21: =IF(AND(N21>=0,N20<0),"✅ PAYBACK","") | Q21: =SUM(M186:M197) -> 1510969.6 | R21: =SUM(I186:I197) -> 68501.719
A22: 2 | B22: Mai | C22: =Premissas!$C$70+0.3333333333*(Premissas!$C$71-Premissas!$C$70) -> 0.96333333 | D22: =(1+Premissas!$C$26)^(1) -> 1.08 | E22: =Dimensionador!$C$22*(Premissas!$C$70+0.3333333333*(Premissas!$C$71-Premissas!$C$70))*Premissas!$C$21*(1+Premissas!$C$26)^(1) -> 19304.942 | F22: =Dimensionador!$C$7*Premissas!$C$13*(Premissas!$C$70+0.3333333333*(Premissas!$C$71-Premissas!$C$70))*Premissas!$C$20*(1+Premissas!$C$26)^(1) -> 5227.8437 | G22: =Dimensionador!$C$7*Premissas!$C$25*(1+Premissas!$C$27)^(1)/12 -> 1888.3333 | H22: =Premissas!$C$56*(1-Premissas!$C$32)^(1) -> 54942.656 | I22: =MIN(H22,Dimensionador!$C$7*Premissas!$C$13*(Premissas!$C$70+0.3333333333*(Premissas!$C$71-Premissas!$C$70))) -> 7733.0509 | J22: =MAX(0,H22-I22) -> 47209.605 | K22: =Premissas!$C$35*(1+Premissas!$C$27)^(1)/12 -> 1019.2708 | L22: =E22-F22+(I22+J22)*Premissas!$C$20*(1+Premissas!$C$26)^(1) -> 51220.475 | M22: =L22-G22-K22 -> 48312.871 | N22: =N21+M22 -> -1517142.6 | O22: =O21+M22 -> 770357.35 | P22: =IF(AND(N22>=0,N21<0),"✅ PAYBACK","") | Q22: =SUM(M198:M209) -> 1619675.7 | R22: =SUM(I198:I209) -> 67056.789
A23: 2 | B23: Jun | C23: =Premissas!$C$70+0.4166666667*(Premissas!$C$71-Premissas!$C$70) -> 0.96141667 | D23: =(1+Premissas!$C$26)^(1) -> 1.08 | E23: =Dimensionador!$C$22*(Premissas!$C$70+0.4166666667*(Premissas!$C$71-Premissas!$C$70))*Premissas!$C$21*(1+Premissas!$C$26)^(1) -> 19266.533 | F23: =Dimensionador!$C$7*Premissas!$C$13*(Premissas!$C$70+0.4166666667*(Premissas!$C$71-Premissas!$C$70))*Premissas!$C$20*(1+Premissas!$C$26)^(1) -> 5217.4422 | G23: =Dimensionador!$C$7*Premissas!$C$25*(1+Premissas!$C$27)^(1)/12 -> 1888.3333 | H23: =Premissas!$C$57*(1-Premissas!$C$32)^(1) -> 53170.312 | I23: =MIN(H23,Dimensionador!$C$7*Premissas!$C$13*(Premissas!$C$70+0.4166666667*(Premissas!$C$71-Premissas!$C$70))) -> 7717.665 | J23: =MAX(0,H23-I23) -> 45452.647 | K23: =Premissas!$C$35*(1+Premissas!$C$27)^(1)/12 -> 1019.2708 | L23: =E23-F23+(I23+J23)*Premissas!$C$20*(1+Premissas!$C$26)^(1) -> 49994.293 | M23: =L23-G23-K23 -> 47086.689 | N23: =N22+M23 -> -1470056 | O23: =O22+M23 -> 817444.04 | P23: =IF(AND(N23>=0,N22<0),"✅ PAYBACK","") | Q23: =SUM(M210:M221) -> 1736007.7 | R23: =SUM(I210:I221) -> 65611.859
A24: 2 | B24: Jul | C24: =Premissas!$C$70+0.5*(Premissas!$C$71-Premissas!$C$70) -> 0.9595 | D24: =(1+Premissas!$C$26)^(1) -> 1.08 | E24: =Dimensionador!$C$22*(Premissas!$C$70+0.5*(Premissas!$C$71-Premissas!$C$70))*Premissas!$C$21*(1+Premissas!$C$26)^(1) -> 19228.123 | F24: =Dimensionador!$C$7*Premissas!$C$13*(Premissas!$C$70+0.5*(Premissas!$C$71-Premissas!$C$70))*Premissas!$C$20*(1+Premissas!$C$26)^(1) -> 5207.0408 | G24: =Dimensionador!$C$7*Premissas!$C$25*(1+Premissas!$C$27)^(1)/12 -> 1888.3333 | H24: =Premissas!$C$58*(1-Premissas!$C$32)^(1) -> 54942.656 | I24: =MIN(H24,Dimensionador!$C$7*Premissas!$C$13*(Premissas!$C$70+0.5*(Premissas!$C$71-Premissas!$C$70))) -> 7702.2792 | J24: =MAX(0,H24-I24) -> 47240.377 | K24: =Premissas!$C$35*(1+Premissas!$C$27)^(1)/12 -> 1019.2708 | L24: =E24-F24+(I24+J24)*Premissas!$C$20*(1+Premissas!$C$26)^(1) -> 51164.459 | M24: =L24-G24-K24 -> 48256.855 | N24: =N23+M24 -> -1421799.1 | O24: =O23+M24 -> 865700.9 | P24: =IF(AND(N24>=0,N23<0),"✅ PAYBACK","") | Q24: =SUM(M222:M233) -> 1860785.7 | R24: =SUM(I222:I233) -> 64211.08
A25: 2 | B25: Ago | C25: =Premissas!$C$70+0.5833333333*(Premissas!$C$71-Premissas!$C$70) -> 0.95758333 | D25: =(1+Premissas!$C$26)^(1) -> 1.08 | E25: =Dimensionador!$C$22*(Premissas!$C$70+0.5833333333*(Premissas!$C$71-Premissas!$C$70))*Premissas!$C$21*(1+Premissas!$C$26)^(1) -> 19189.714 | F25: =Dimensionador!$C$7*Premissas!$C$13*(Premissas!$C$70+0.5833333333*(Premissas!$C$71-Premissas!$C$70))*Premissas!$C$20*(1+Premissas!$C$26)^(1) -> 5196.6394 | G25: =Dimensionador!$C$7*Premissas!$C$25*(1+Premissas!$C$27)^(1)/12 -> 1888.3333 | H25: =Premissas!$C$59*(1-Premissas!$C$32)^(1) -> 54942.656 | I25: =MIN(H25,Dimensionador!$C$7*Premissas!$C$13*(Premissas!$C$70+0.5833333333*(Premissas!$C$71-Premissas!$C$70))) -> 7686.8934 | J25: =MAX(0,H25-I25) -> 47255.763 | K25: =Premissas!$C$35*(1+Premissas!$C$27)^(1)/12 -> 1019.2708 | L25: =E25-F25+(I25+J25)*Premissas!$C$20*(1+Premissas!$C$26)^(1) -> 51136.451 | M25: =L25-G25-K25 -> 48228.847 | N25: =N24+M25 -> -1373570.3 | O25: =O24+M25 -> 913929.74 | P25: =IF(AND(N25>=0,N24<0),"✅ PAYBACK","") | Q25: =SUM(M234:M245) -> 1994697.8 | R25: =SUM(I234:I245) -> 62862.479
A26: 2 | B26: Set | C26: =Premissas!$C$70+0.6666666667*(Premissas!$C$71-Premissas!$C$70) -> 0.95566667 | D26: =(1+Premissas!$C$26)^(1) -> 1.08 | E26: =Dimensionador!$C$22*(Premissas!$C$70+0.6666666667*(Premissas!$C$71-Premissas!$C$70))*Premissas!$C$21*(1+Premissas!$C$26)^(1) -> 19151.304 | F26: =Dimensionador!$C$7*Premissas!$C$13*(Premissas!$C$70+0.6666666667*(Premissas!$C$71-Premissas!$C$70))*Premissas!$C$20*(1+Premissas!$C$26)^(1) -> 5186.238 | G26: =Dimensionador!$C$7*Premissas!$C$25*(1+Premissas!$C$27)^(1)/12 -> 1888.3333 | H26: =Premissas!$C$60*(1-Premissas!$C$32)^(1) -> 53170.312 | I26: =MIN(H26,Dimensionador!$C$7*Premissas!$C$13*(Premissas!$C$70+0.6666666667*(Premissas!$C$71-Premissas!$C$70))) -> 7671.5075 | J26: =MAX(0,H26-I26) -> 45498.805 | K26: =Premissas!$C$35*(1+Premissas!$C$27)^(1)/12 -> 1019.2708 | L26: =E26-F26+(I26+J26)*Premissas!$C$20*(1+Premissas!$C$26)^(1) -> 49910.269 | M26: =L26-G26-K26 -> 47002.665 | N26: =N25+M26 -> -1326567.6 | O26: =O25+M26 -> 960932.41 | P26: =IF(AND(N26>=0,N25<0),"✅ PAYBACK","") | Q26: =I26 -> 7671.5075
A27: 2 | B27: Out | C27: =Premissas!$C$70+0.75*(Premissas!$C$71-Premissas!$C$70) -> 0.95375 | D27: =(1+Premissas!$C$26)^(1) -> 1.08 | E27: =Dimensionador!$C$22*(Premissas!$C$70+0.75*(Premissas!$C$71-Premissas!$C$70))*Premissas!$C$21*(1+Premissas!$C$26)^(1) -> 19112.895 | F27: =Dimensionador!$C$7*Premissas!$C$13*(Premissas!$C$70+0.75*(Premissas!$C$71-Premissas!$C$70))*Premissas!$C$20*(1+Premissas!$C$26)^(1) -> 5175.8366 | G27: =Dimensionador!$C$7*Premissas!$C$25*(1+Premissas!$C$27)^(1)/12 -> 1888.3333 | H27: =Premissas!$C$61*(1-Premissas!$C$32)^(1) -> 54942.656 | I27: =MIN(H27,Dimensionador!$C$7*Premissas!$C$13*(Premissas!$C$70+0.75*(Premissas!$C$71-Premissas!$C$70))) -> 7656.1217 | J27: =MAX(0,H27-I27) -> 47286.535 | K27: =Premissas!$C$35*(1+Premissas!$C$27)^(1)/12 -> 1019.2708 | L27: =E27-F27+(I27+J27)*Premissas!$C$20*(1+Premissas!$C$26)^(1) -> 51080.435 | M27: =L27-G27-K27 -> 48172.83 | N27: =N26+M27 -> -1278394.8 | O27: =O26+M27 -> 1009105.2 | P27: =IF(AND(N27>=0,N26<0),"✅ PAYBACK","") | Q27: =I27 -> 7656.1217
A28: 2 | B28: Nov | C28: =Premissas!$C$70+0.8333333333*(Premissas!$C$71-Premissas!$C$70) -> 0.95183333 | D28: =(1+Premissas!$C$26)^(1) -> 1.08 | E28: =Dimensionador!$C$22*(Premissas!$C$70+0.8333333333*(Premissas!$C$71-Premissas!$C$70))*Premissas!$C$21*(1+Premissas!$C$26)^(1) -> 19074.485 | F28: =Dimensionador!$C$7*Premissas!$C$13*(Premissas!$C$70+0.8333333333*(Premissas!$C$71-Premissas!$C$70))*Premissas!$C$20*(1+Premissas!$C$26)^(1) -> 5165.4351 | G28: =Dimensionador!$C$7*Premissas!$C$25*(1+Premissas!$C$27)^(1)/12 -> 1888.3333 | H28: =Premissas!$C$62*(1-Premissas!$C$32)^(1) -> 53170.312 | I28: =MIN(H28,Dimensionador!$C$7*Premissas!$C$13*(Premissas!$C$70+0.8333333333*(Premissas!$C$71-Premissas!$C$70))) -> 7640.7359 | J28: =MAX(0,H28-I28) -> 45529.577 | K28: =Premissas!$C$35*(1+Premissas!$C$27)^(1)/12 -> 1019.2708 | L28: =E28-F28+(I28+J28)*Premissas!$C$20*(1+Premissas!$C$26)^(1) -> 49854.253 | M28: =L28-G28-K28 -> 46946.649 | N28: =N27+M28 -> -1231448.1 | O28: =O27+M28 -> 1056051.9 | P28: =IF(AND(N28>=0,N27<0),"✅ PAYBACK","") | Q28: =I28 -> 7640.7359
A29: 2 | B29: Dez | C29: =Premissas!$C$70+0.9166666667*(Premissas!$C$71-Premissas!$C$70) -> 0.94991667 | D29: =(1+Premissas!$C$26)^(1) -> 1.08 | E29: =Dimensionador!$C$22*(Premissas!$C$70+0.9166666667*(Premissas!$C$71-Premissas!$C$70))*Premissas!$C$21*(1+Premissas!$C$26)^(1) -> 19036.076 | F29: =Dimensionador!$C$7*Premissas!$C$13*(Premissas!$C$70+0.9166666667*(Premissas!$C$71-Premissas!$C$70))*Premissas!$C$20*(1+Premissas!$C$26)^(1) -> 5155.0337 | G29: =Dimensionador!$C$7*Premissas!$C$25*(1+Premissas!$C$27)^(1)/12 -> 1888.3333 | H29: =Premissas!$C$63*(1-Premissas!$C$32)^(1) -> 54942.656 | I29: =MIN(H29,Dimensionador!$C$7*Premissas!$C$13*(Premissas!$C$70+0.9166666667*(Premissas!$C$71-Premissas!$C$70))) -> 7625.3501 | J29: =MAX(0,H29-I29) -> 47317.306 | K29: =Premissas!$C$35*(1+Premissas!$C$27)^(1)/12 -> 1019.2708 | L29: =E29-F29+(I29+J29)*Premissas!$C$20*(1+Premissas!$C$26)^(1) -> 51024.418 | M29: =L29-G29-K29 -> 48116.814 | N29: =N28+M29 -> -1183331.3 | O29: =O28+M29 -> 1104168.7 | P29: =IF(AND(N29>=0,N28<0),"✅ PAYBACK","") | Q29: =I29 -> 7625.3501
A30: 3 | B30: Jan | C30: =Premissas!$C$71+0*(Premissas!$C$72-Premissas!$C$71) -> 0.948 | D30: =(1+Premissas!$C$26)^(2) -> 1.1664 | E30: =Dimensionador!$C$22*(Premissas!$C$71+0*(Premissas!$C$72-Premissas!$C$71))*Premissas!$C$21*(1+Premissas!$C$26)^(2) -> 20517.48 | F30: =Dimensionador!$C$7*Premissas!$C$13*(Premissas!$C$71+0*(Premissas!$C$72-Premissas!$C$71))*Premissas!$C$20*(1+Premissas!$C$26)^(2) -> 5556.2029 | G30: =Dimensionador!$C$7*Premissas!$C$25*(1+Premissas!$C$27)^(2)/12 -> 1944.9833 | H30: =Premissas!$C$52*(1-Premissas!$C$32)^(2) -> 54667.943 | I30: =MIN(H30,Dimensionador!$C$7*Premissas!$C$13*(Premissas!$C$71+0*(Premissas!$C$72-Premissas!$C$71))) -> 7609.9642 | J30: =MAX(0,H30-I30) -> 47057.979 | K30: =Premissas!$C$35*(1+Premissas!$C$27)^(2)/12 -> 1049.849 | L30: =E30-F30+(I30+J30)*Premissas!$C$20*(1+Premissas!$C$26)^(2) -> 54875.549 | M30: =L30-G30-K30 -> 51880.717 | N30: =N29+M30 -> -1131450.6 | O30: =O29+M30 -> 1156049.4 | P30: =IF(AND(N30>=0,N29<0),"✅ PAYBACK","") | Q30: =I30 -> 7609.9642
A31: 3 | B31: Fev | C31: =Premissas!$C$71+0.0833333333*(Premissas!$C$72-Premissas!$C$71) -> 0.94625 | D31: =(1+Premissas!$C$26)^(2) -> 1.1664 | E31: =Dimensionador!$C$22*(Premissas!$C$71+0.0833333333*(Premissas!$C$72-Premissas!$C$71))*Premissas!$C$21*(1+Premissas!$C$26)^(2) -> 20479.605 | F31: =Dimensionador!$C$7*Premissas!$C$13*(Premissas!$C$71+0.0833333333*(Premissas!$C$72-Premissas!$C$71))*Premissas!$C$20*(1+Premissas!$C$26)^(2) -> 5545.9462 | G31: =Dimensionador!$C$7*Premissas!$C$25*(1+Premissas!$C$27)^(2)/12 -> 1944.9833 | H31: =Premissas!$C$53*(1-Premissas!$C$32)^(2) -> 49377.497 | I31: =MIN(H31,Dimensionador!$C$7*Premissas!$C$13*(Premissas!$C$71+0.0833333333*(Premissas!$C$72-Premissas!$C$71))) -> 7595.9163 | J31: =MAX(0,H31-I31) -> 41781.581 | K31: =Premissas!$C$35*(1+Premissas!$C$27)^(2)/12 -> 1049.849 | L31: =E31-F31+(I31+J31)*Premissas!$C$20*(1+Premissas!$C$26)^(2) -> 50985.259 | M31: =L31-G31-K31 -> 47990.427 | N31: =N30+M31 -> -1083460.2 | O31: =O30+M31 -> 1204039.8 | P31: =IF(AND(N31>=0,N30<0),"✅ PAYBACK","") | Q31: =I31 -> 7595.9163
A32: 3 | B32: Mar | C32: =Premissas!$C$71+0.1666666667*(Premissas!$C$72-Premissas!$C$71) -> 0.9445 | D32: =(1+Premissas!$C$26)^(2) -> 1.1664 | E32: =Dimensionador!$C$22*(Premissas!$C$71+0.1666666667*(Premissas!$C$72-Premissas!$C$71))*Premissas!$C$21*(1+Premissas!$C$26)^(2) -> 20441.73 | F32: =Dimensionador!$C$7*Premissas!$C$13*(Premissas!$C$71+0.1666666667*(Premissas!$C$72-Premissas!$C$71))*Premissas!$C$20*(1+Premissas!$C$26)^(2) -> 5535.6895 | G32: =Dimensionador!$C$7*Premissas!$C$25*(1+Premissas!$C$27)^(2)/12 -> 1944.9833 | H32: =Premissas!$C$54*(1-Premissas!$C$32)^(2) -> 54667.943 | I32: =MIN(H32,Dimensionador!$C$7*Premissas!$C$13*(Premissas!$C$71+0.1666666667*(Premissas!$C$72-Premissas!$C$71))) -> 7581.8684 | J32: =MAX(0,H32-I32) -> 47086.075 | K32: =Premissas!$C$35*(1+Premissas!$C$27)^(2)/12 -> 1049.849 | L32: =E32-F32+(I32+J32)*Premissas!$C$20*(1+Premissas!$C$26)^(2) -> 54820.312 | M32: =L32-G32-K32 -> 51825.48 | N32: =N31+M32 -> -1031634.7 | O32: =O31+M32 -> 1255865.3 | P32: =IF(AND(N32>=0,N31<0),"✅ PAYBACK","") | Q32: =I32 -> 7581.8684
A33: 3 | B33: Abr | C33: =Premissas!$C$71+0.25*(Premissas!$C$72-Premissas!$C$71) -> 0.94275 | D33: =(1+Premissas!$C$26)^(2) -> 1.1664 | E33: =Dimensionador!$C$22*(Premissas!$C$71+0.25*(Premissas!$C$72-Premissas!$C$71))*Premissas!$C$21*(1+Premissas!$C$26)^(2) -> 20403.855 | F33: =Dimensionador!$C$7*Premissas!$C$13*(Premissas!$C$71+0.25*(Premissas!$C$72-Premissas!$C$71))*Premissas!$C$20*(1+Premissas!$C$26)^(2) -> 5525.4328 | G33: =Dimensionador!$C$7*Premissas!$C$25*(1+Premissas!$C$27)^(2)/12 -> 1944.9833 | H33: =Premissas!$C$55*(1-Premissas!$C$32)^(2) -> 52904.461 | I33: =MIN(H33,Dimensionador!$C$7*Premissas!$C$13*(Premissas!$C$71+0.25*(Premissas!$C$72-Premissas!$C$71))) -> 7567.8204 | J33: =MAX(0,H33-I33) -> 45336.64 | K33: =Premissas!$C$35*(1+Premissas!$C$27)^(2)/12 -> 1049.849 | L33: =E33-F33+(I33+J33)*Premissas!$C$20*(1+Premissas!$C$26)^(2) -> 53505.137 | M33: =L33-G33-K33 -> 50510.304 | N33: =N32+M33 -> -981124.37 | O33: =O32+M33 -> 1306375.6 | P33: =IF(AND(N33>=0,N32<0),"✅ PAYBACK","") | Q33: =I33 -> 7567.8204
A34: 3 | B34: Mai | C34: =Premissas!$C$71+0.3333333333*(Premissas!$C$72-Premissas!$C$71) -> 0.941 | D34: =(1+Premissas!$C$26)^(2) -> 1.1664 | E34: =Dimensionador!$C$22*(Premissas!$C$71+0.3333333333*(Premissas!$C$72-Premissas!$C$71))*Premissas!$C$21*(1+Premissas!$C$26)^(2) -> 20365.979 | F34: =Dimensionador!$C$7*Premissas!$C$13*(Premissas!$C$71+0.3333333333*(Premissas!$C$72-Premissas!$C$71))*Premissas!$C$20*(1+Premissas!$C$26)^(2) -> 5515.1761 | G34: =Dimensionador!$C$7*Premissas!$C$25*(1+Premissas!$C$27)^(2)/12 -> 1944.9833 | H34: =Premissas!$C$56*(1-Premissas!$C$32)^(2) -> 54667.943 | I34: =MIN(H34,Dimensionador!$C$7*Premissas!$C$13*(Premissas!$C$71+0.3333333333*(Premissas!$C$72-Premissas!$C$71))) -> 7553.7725 | J34: =MAX(0,H34-I34) -> 47114.17 | K34: =Premissas!$C$35*(1+Premissas!$C$27)^(2)/12 -> 1049.849 | L34: =E34-F34+(I34+J34)*Premissas!$C$20*(1+Premissas!$C$26)^(2) -> 54765.075 | M34: =L34-G34-K34 -> 51770.243 | N34: =N33+M34 -> -929354.13 | O34: =O33+M34 -> 1358145.9 | P34: =IF(AND(N34>=0,N33<0),"✅ PAYBACK","") | Q34: =I34 -> 7553.7725
A35: 3 | B35: Jun | C35: =Premissas!$C$71+0.4166666667*(Premissas!$C$72-Premissas!$C$71) -> 0.93925 | D35: =(1+Premissas!$C$26)^(2) -> 1.1664 | E35: =Dimensionador!$C$22*(Premissas!$C$71+0.4166666667*(Premissas!$C$72-Premissas!$C$71))*Premissas!$C$21*(1+Premissas!$C$26)^(2) -> 20328.104 | F35: =Dimensionador!$C$7*Premissas!$C$13*(Premissas!$C$71+0.4166666667*(Premissas!$C$72-Premissas!$C$71))*Premissas!$C$20*(1+Premissas!$C$26)^(2) -> 5504.9194 | G35: =Dimensionador!$C$7*Premissas!$C$25*(1+Premissas!$C$27)^(2)/12 -> 1944.9833 | H35: =Premissas!$C$57*(1-Premissas!$C$32)^(2) -> 52904.461 | I35: =MIN(H35,Dimensionador!$C$7*Premissas!$C$13*(Premissas!$C$71+0.4166666667*(Premissas!$C$72-Premissas!$C$71))) -> 7539.7246 | J35: =MAX(0,H35-I35) -> 45364.736 | K35: =Premissas!$C$35*(1+Premissas!$C$27)^(2)/12 -> 1049.849 | L35: =E35-F35+(I35+J35)*Premissas!$C$20*(1+Premissas!$C$26)^(2) -> 53449.9 | M35: =L35-G35-K35 -> 50455.068 | N35: =N34+M35 -> -878899.06 | O35: =O34+M35 -> 1408600.9 | P35: =IF(AND(N35>=0,N34<0),"✅ PAYBACK","") | Q35: =I35 -> 7539.7246
A36: 3 | B36: Jul | C36: =Premissas!$C$71+0.5*(Premissas!$C$72-Premissas!$C$71) -> 0.9375 | D36: =(1+Premissas!$C$26)^(2) -> 1.1664 | E36: =Dimensionador!$C$22*(Premissas!$C$71+0.5*(Premissas!$C$72-Premissas!$C$71))*Premissas!$C$21*(1+Premissas!$C$26)^(2) -> 20290.229 | F36: =Dimensionador!$C$7*Premissas!$C$13*(Premissas!$C$71+0.5*(Premissas!$C$72-Premissas!$C$71))*Premissas!$C$20*(1+Premissas!$C$26)^(2) -> 5494.6627 | G36: =Dimensionador!$C$7*Premissas!$C$25*(1+Premissas!$C$27)^(2)/12 -> 1944.9833 | H36: =Premissas!$C$58*(1-Premissas!$C$32)^(2) -> 54667.943 | I36: =MIN(H36,Dimensionador!$C$7*Premissas!$C$13*(Premissas!$C$71+0.5*(Premissas!$C$72-Premissas!$C$71))) -> 7525.6767 | J36: =MAX(0,H36-I36) -> 47142.266 | K36: =Premissas!$C$35*(1+Premissas!$C$27)^(2)/12 -> 1049.849 | L36: =E36-F36+(I36+J36)*Premissas!$C$20*(1+Premissas!$C$26)^(2) -> 54709.839 | M36: =L36-G36-K36 -> 51715.006 | N36: =N35+M36 -> -827184.05 | O36: =O35+M36 -> 1460315.9 | P36: =IF(AND(N36>=0,N35<0),"✅ PAYBACK","") | Q36: =I36 -> 7525.6767
A37: 3 | B37: Ago | C37: =Premissas!$C$71+0.5833333333*(Premissas!$C$72-Premissas!$C$71) -> 0.93575 | D37: =(1+Premissas!$C$26)^(2) -> 1.1664 | E37: =Dimensionador!$C$22*(Premissas!$C$71+0.5833333333*(Premissas!$C$72-Premissas!$C$71))*Premissas!$C$21*(1+Premissas!$C$26)^(2) -> 20252.354 | F37: =Dimensionador!$C$7*Premissas!$C$13*(Premissas!$C$71+0.5833333333*(Premissas!$C$72-Premissas!$C$71))*Premissas!$C$20*(1+Premissas!$C$26)^(2) -> 5484.406 | G37: =Dimensionador!$C$7*Premissas!$C$25*(1+Premissas!$C$27)^(2)/12 -> 1944.9833 | H37: =Premissas!$C$59*(1-Premissas!$C$32)^(2) -> 54667.943 | I37: =MIN(H37,Dimensionador!$C$7*Premissas!$C$13*(Premissas!$C$71+0.5833333333*(Premissas!$C$72-Premissas!$C$71))) -> 7511.6287 | J37: =MAX(0,H37-I37) -> 47156.314 | K37: =Premissas!$C$35*(1+Premissas!$C$27)^(2)/12 -> 1049.849 | L37: =E37-F37+(I37+J37)*Premissas!$C$20*(1+Premissas!$C$26)^(2) -> 54682.22 | M37: =L37-G37-K37 -> 51687.388 | N37: =N36+M37 -> -775496.67 | O37: =O36+M37 -> 1512003.3 | P37: =IF(AND(N37>=0,N36<0),"✅ PAYBACK","") | Q37: =I37 -> 7511.6287
A38: 3 | B38: Set | C38: =Premissas!$C$71+0.6666666667*(Premissas!$C$72-Premissas!$C$71) -> 0.934 | D38: =(1+Premissas!$C$26)^(2) -> 1.1664 | E38: =Dimensionador!$C$22*(Premissas!$C$71+0.6666666667*(Premissas!$C$72-Premissas!$C$71))*Premissas!$C$21*(1+Premissas!$C$26)^(2) -> 20214.479 | F38: =Dimensionador!$C$7*Premissas!$C$13*(Premissas!$C$71+0.6666666667*(Premissas!$C$72-Premissas!$C$71))*Premissas!$C$20*(1+Premissas!$C$26)^(2) -> 5474.1493 | G38: =Dimensionador!$C$7*Premissas!$C$25*(1+Premissas!$C$27)^(2)/12 -> 1944.9833 | H38: =Premissas!$C$60*(1-Premissas!$C$32)^(2) -> 52904.461 | I38: =MIN(H38,Dimensionador!$C$7*Premissas!$C$13*(Premissas!$C$71+0.6666666667*(Premissas!$C$72-Premissas!$C$71))) -> 7497.5808 | J38: =MAX(0,H38-I38) -> 45406.88 | K38: =Premissas!$C$35*(1+Premissas!$C$27)^(2)/12 -> 1049.849 | L38: =E38-F38+(I38+J38)*Premissas!$C$20*(1+Premissas!$C$26)^(2) -> 53367.045 | M38: =L38-G38-K38 -> 50372.212 | N38: =N37+M38 -> -725124.45 | O38: =O37+M38 -> 1562375.5 | P38: =IF(AND(N38>=0,N37<0),"✅ PAYBACK","") | Q38: =I38 -> 7497.5808
A39: 3 | B39: Out | C39: =Premissas!$C$71+0.75*(Premissas!$C$72-Premissas!$C$71) -> 0.93225 | D39: =(1+Premissas!$C$26)^(2) -> 1.1664 | E39: =Dimensionador!$C$22*(Premissas!$C$71+0.75*(Premissas!$C$72-Premissas!$C$71))*Premissas!$C$21*(1+Premissas!$C$26)^(2) -> 20176.604 | F39: =Dimensionador!$C$7*Premissas!$C$13*(Premissas!$C$71+0.75*(Premissas!$C$72-Premissas!$C$71))*Premissas!$C$20*(1+Premissas!$C$26)^(2) -> 5463.8926 | G39: =Dimensionador!$C$7*Premissas!$C$25*(1+Premissas!$C$27)^(2)/12 -> 1944.9833 | H39: =Premissas!$C$61*(1-Premissas!$C$32)^(2) -> 54667.943 | I39: =MIN(H39,Dimensionador!$C$7*Premissas!$C$13*(Premissas!$C$71+0.75*(Premissas!$C$72-Premissas!$C$71))) -> 7483.5329 | J39: =MAX(0,H39-I39) -> 47184.41 | K39: =Premissas!$C$35*(1+Premissas!$C$27)^(2)/12 -> 1049.849 | L39: =E39-F39+(I39+J39)*Premissas!$C$20*(1+Premissas!$C$26)^(2) -> 54626.983 | M39: =L39-G39-K39 -> 51632.151 | N39: =N38+M39 -> -673492.3 | O39: =O38+M39 -> 1614007.7 | P39: =IF(AND(N39>=0,N38<0),"✅ PAYBACK","") | Q39: =I39 -> 7483.5329
A40: 3 | B40: Nov | C40: =Premissas!$C$71+0.8333333333*(Premissas!$C$72-Premissas!$C$71) -> 0.9305 | D40: =(1+Premissas!$C$26)^(2) -> 1.1664 | E40: =Dimensionador!$C$22*(Premissas!$C$71+0.8333333333*(Premissas!$C$72-Premissas!$C$71))*Premissas!$C$21*(1+Premissas!$C$26)^(2) -> 20138.729 | F40: =Dimensionador!$C$7*Premissas!$C$13*(Premissas!$C$71+0.8333333333*(Premissas!$C$72-Premissas!$C$71))*Premissas!$C$20*(1+Premissas!$C$26)^(2) -> 5453.6359 | G40: =Dimensionador!$C$7*Premissas!$C$25*(1+Premissas!$C$27)^(2)/12 -> 1944.9833 | H40: =Premissas!$C$62*(1-Premissas!$C$32)^(2) -> 52904.461 | I40: =MIN(H40,Dimensionador!$C$7*Premissas!$C$13*(Premissas!$C$71+0.8333333333*(Premissas!$C$72-Premissas!$C$71))) -> 7469.4849 | J40: =MAX(0,H40-I40) -> 45434.976 | K40: =Premissas!$C$35*(1+Premissas!$C$27)^(2)/12 -> 1049.849 | L40: =E40-F40+(I40+J40)*Premissas!$C$20*(1+Premissas!$C$26)^(2) -> 53311.808 | M40: =L40-G40-K40 -> 50316.976 | N40: =N39+M40 -> -623175.33 | O40: =O39+M40 -> 1664324.7 | P40: =IF(AND(N40>=0,N39<0),"✅ PAYBACK","") | Q40: =I40 -> 7469.4849
A41: 3 | B41: Dez | C41: =Premissas!$C$71+0.9166666667*(Premissas!$C$72-Premissas!$C$71) -> 0.92875 | D41: =(1+Premissas!$C$26)^(2) -> 1.1664 | E41: =Dimensionador!$C$22*(Premissas!$C$71+0.9166666667*(Premissas!$C$72-Premissas!$C$71))*Premissas!$C$21*(1+Premissas!$C$26)^(2) -> 20100.854 | F41: =Dimensionador!$C$7*Premissas!$C$13*(Premissas!$C$71+0.9166666667*(Premissas!$C$72-Premissas!$C$71))*Premissas!$C$20*(1+Premissas!$C$26)^(2) -> 5443.3791 | G41: =Dimensionador!$C$7*Premissas!$C$25*(1+Premissas!$C$27)^(2)/12 -> 1944.9833 | H41: =Premissas!$C$63*(1-Premissas!$C$32)^(2) -> 54667.943 | I41: =MIN(H41,Dimensionador!$C$7*Premissas!$C$13*(Premissas!$C$71+0.9166666667*(Premissas!$C$72-Premissas!$C$71))) -> 7455.437 | J41: =MAX(0,H41-I41) -> 47212.506 | K41: =Premissas!$C$35*(1+Premissas!$C$27)^(2)/12 -> 1049.849 | L41: =E41-F41+(I41+J41)*Premissas!$C$20*(1+Premissas!$C$26)^(2) -> 54571.747 | M41: =L41-G41-K41 -> 51576.914 | N41: =N40+M41 -> -571598.41 | O41: =O40+M41 -> 1715901.6 | P41: =IF(AND(N41>=0,N40<0),"✅ PAYBACK","") | Q41: =I41 -> 7455.437
...

Sheet Premissas
A1: PREMISSAS — BESS LOAD SHIFTING
A2: Azul = input editável | Verde = calculado | Vinculado ao Dimensionador
B4: EQUIPAMENTO BESS | C4: VALOR | D4: UNIDADE
B5: Potência BESS | C5: 241 | D5: kW
B6: DoD | C6: 1 | D6: p.u.
B7: η BESS round-trip | C7: 0.9556 | D7: p.u.
B8: η Elétrica | C8: 0.98 | D8: p.u.
B9: η Operacional | C9: 0.99 | D9: p.u.
B10: Dias úteis/mês | C10: 21 | D10: dias
B11: Energia útil/ciclo [calc] | C11: =C5*C6*C7*C8*C9 -> 223.43667 | D11: kWh
B12: Energia útil/mês 1 BESS [calc] | C12: =C11*C10*J12 -> 3450.0001 | D12: kWh | G12: 4692.17 | H12: =Dimensionador!C5/2 -> 3450 | J12: =H12/G12 -> 0.73526748
B13: Energia carga/mês 1 BESS [calc] | C13: =(C5*C10*C6)/(C7*C8*C9)*J12 -> 4013.6942 | D13: kWh | G13: =C13*2 -> 8027.3884
B15: TARIFAS — MERCADO LIVRE | C15: VALOR | D15: UNIDADE
B16: TUSD Fora Ponta | C16: 0.625962 | D16: R$/kWh
B17: TE Fora Ponta ML | C17: 0 | D17: R$/kWh
B18: TUSD Na Ponta | C18: 2.689175 | D18: R$/kWh
B19: TE Na Ponta ML | C19: 0 | D19: R$/kWh
B20: HFP Total [calc] | C20: =C16+C17 -> 0.625962 | D20: R$/kWh
B21: HP Total [calc] | C21: =C18+C19 -> 2.689175 | D21: R$/kWh
B22: Delta HP-HFP [calc] | C22: =C21-C20 -> 2.063213 | D22: R$/kWh
B24: PARÂMETROS FINANCEIROS | C24: VALOR | D24: UNIDADE
B25: O&M por BESS/ano | C25: =Dimensionador!C8*1% -> 11000 | D25: R$/ano
B26: Reajuste energia | C26: 0.08 | D26: % a.a.
B27: Reajuste O&M | C27: 0.03 | D27: % a.a.
B28: TMA | C28: 0.12 | D28: % a.a.
A29: ⑤ SISTEMA SOLAR FOTOVOLTAICO
B30: Potência instalada (kWp) | C30: 475 | D30: kWp | E30: Input: tamanho do sistema solar
B31: Performance Ratio (PR) | C31: 0.75 | D31: p.u. | E31: Tipicamente 75-82% para sistemas C&I
B32: Degradação painéis (a.a.) | C32: 0.005 | D32: % a.a. | E32: Tipicamente 0,5% a.a.
B33: CAPEX solar total | C33: 1187500 | D33: R$ | E33: Equipamentos + instalação + comissionamento
B34: O&M solar (% CAPEX/ano) | C34: 0.01 | D34: % a.a. | E34: Tipicamente 0,5–1,5% do CAPEX solar/ano
B35: O&M solar ano 1 (R$) | C35: =C33*C34 -> 11875 | E35: CAPEX solar × % O&M
B36: Energia solar base/dia | C36: =C30*C31 -> 356.25 | E36: kWp × PR (sem HSP)
A37: IRRADIÂNCIA — HSP MENSAL (h/dia) — preencher com dados CRESESB
B38: Janeiro | C38: 5 | D38: h/dia | E38: HSP médio de Janeiro — fonte: CRESESB / PVGIS
B39: Fevereiro | C39: 5 | D39: h/dia | E39: HSP médio de Fevereiro — fonte: CRESESB / PVGIS
B40: Março | C40: 5 | D40: h/dia | E40: HSP médio de Março — fonte: CRESESB / PVGIS
B41: Abril | C41: 5 | D41: h/dia | E41: HSP médio de Abril — fonte: CRESESB / PVGIS
B42: Maio | C42: 5 | D42: h/dia | E42: HSP médio de Maio — fonte: CRESESB / PVGIS
B43: Junho | C43: 5 | D43: h/dia | E43: HSP médio de Junho — fonte: CRESESB / PVGIS
...
